DEBUG 2018-02-04 23:49:33,441 utils 12568 11988 (0.002) 
            SELECT name, type FROM sqlite_master
            WHERE type in ('table', 'view') AND NOT name='sqlite_sequence'
            ORDER BY name; args=None
DEBUG 2018-02-04 23:49:33,445 utils 12568 11988 (0.000) SELECT "django_migrations"."app", "django_migrations"."name" FROM "django_migrations"; args=()
DEBUG 2018-02-04 23:49:34,852 utils 12568 16816 (0.001) SELECT "Users"."last_login", "Users"."is_superuser", "Users"."id", "Users"."uuid", "Users"."email", "Users"."name", "Users"."password", "Users"."phone_number", "Users"."role", "Users"."last_login_at", "Users"."created_at", "Users"."updated_at" FROM "Users" WHERE "Users"."email" = 'user1@gmail.com'; args=('user1@gmail.com',)
ERROR 2018-02-04 23:49:34,853 response 12568 16816 Success
NoneType: None
DEBUG 2018-02-04 23:49:34,855 utils 12568 16816 (0.001) SELECT "Locations"."id", "Locations"."lat", "Locations"."lng", "Locations"."time", "Locations"."next_location_id", "Locations"."user_id" FROM "Locations"; args=()
DEBUG 2018-02-04 23:49:34,864 utils 12568 16816 (0.001) SELECT "Users"."last_login", "Users"."is_superuser", "Users"."id", "Users"."uuid", "Users"."email", "Users"."name", "Users"."password", "Users"."phone_number", "Users"."role", "Users"."last_login_at", "Users"."created_at", "Users"."updated_at" FROM "Users" WHERE "Users"."id" = 2; args=(2,)
DEBUG 2018-02-04 23:49:34,871 utils 12568 16816 (0.001) SELECT "Users"."last_login", "Users"."is_superuser", "Users"."id", "Users"."uuid", "Users"."email", "Users"."name", "Users"."password", "Users"."phone_number", "Users"."role", "Users"."last_login_at", "Users"."created_at", "Users"."updated_at" FROM "Users" WHERE "Users"."id" = 2; args=(2,)
DEBUG 2018-02-04 23:49:34,874 utils 12568 16816 (0.000) SELECT "Users"."last_login", "Users"."is_superuser", "Users"."id", "Users"."uuid", "Users"."email", "Users"."name", "Users"."password", "Users"."phone_number", "Users"."role", "Users"."last_login_at", "Users"."created_at", "Users"."updated_at" FROM "Users" WHERE "Users"."id" = 2; args=(2,)
INFO 2018-02-04 23:49:34,876 basehttp 12568 16816 "GET /lct_app/v1/locations HTTP/1.1" 200 1228
DEBUG 2018-02-04 23:49:43,904 utils 12568 17384 (0.001) SELECT "Users"."last_login", "Users"."is_superuser", "Users"."id", "Users"."uuid", "Users"."email", "Users"."name", "Users"."password", "Users"."phone_number", "Users"."role", "Users"."last_login_at", "Users"."created_at", "Users"."updated_at" FROM "Users" WHERE "Users"."email" = 'user1@gmail.com'; args=('user1@gmail.com',)
ERROR 2018-02-04 23:49:43,905 response 12568 17384 Success
NoneType: None
DEBUG 2018-02-04 23:49:43,906 utils 12568 17384 (0.000) SELECT "Locations"."id", "Locations"."lat", "Locations"."lng", "Locations"."time", "Locations"."next_location_id", "Locations"."user_id" FROM "Locations"; args=()
DEBUG 2018-02-04 23:49:43,909 utils 12568 17384 (0.000) SELECT "Users"."last_login", "Users"."is_superuser", "Users"."id", "Users"."uuid", "Users"."email", "Users"."name", "Users"."password", "Users"."phone_number", "Users"."role", "Users"."last_login_at", "Users"."created_at", "Users"."updated_at" FROM "Users" WHERE "Users"."id" = 2; args=(2,)
DEBUG 2018-02-04 23:49:43,912 utils 12568 17384 (0.001) SELECT "Users"."last_login", "Users"."is_superuser", "Users"."id", "Users"."uuid", "Users"."email", "Users"."name", "Users"."password", "Users"."phone_number", "Users"."role", "Users"."last_login_at", "Users"."created_at", "Users"."updated_at" FROM "Users" WHERE "Users"."id" = 2; args=(2,)
DEBUG 2018-02-04 23:49:43,914 utils 12568 17384 (0.000) SELECT "Users"."last_login", "Users"."is_superuser", "Users"."id", "Users"."uuid", "Users"."email", "Users"."name", "Users"."password", "Users"."phone_number", "Users"."role", "Users"."last_login_at", "Users"."created_at", "Users"."updated_at" FROM "Users" WHERE "Users"."id" = 2; args=(2,)
INFO 2018-02-04 23:49:43,916 basehttp 12568 17384 "GET /lct_app/v1/locations HTTP/1.1" 200 1228
DEBUG 2018-02-04 23:49:57,211 utils 12568 18180 (0.003) SELECT "Users"."last_login", "Users"."is_superuser", "Users"."id", "Users"."uuid", "Users"."email", "Users"."name", "Users"."password", "Users"."phone_number", "Users"."role", "Users"."last_login_at", "Users"."created_at", "Users"."updated_at" FROM "Users" WHERE "Users"."email" = 'user1@gmail.com'; args=('user1@gmail.com',)
DEBUG 2018-02-04 23:49:57,214 utils 12568 18180 (0.000) SELECT "Users"."last_login", "Users"."is_superuser", "Users"."id", "Users"."uuid", "Users"."email", "Users"."name", "Users"."password", "Users"."phone_number", "Users"."role", "Users"."last_login_at", "Users"."created_at", "Users"."updated_at" FROM "Users" WHERE "Users"."id" = 2; args=(2,)
DEBUG 2018-02-04 23:49:57,218 utils 12568 18180 (0.000) SELECT "Locations"."id", "Locations"."lat", "Locations"."lng", "Locations"."time", "Locations"."next_location_id", "Locations"."user_id" FROM "Locations" WHERE "Locations"."user_id" = 2; args=(2,)
DEBUG 2018-02-04 23:49:57,221 utils 12568 18180 (0.000) SELECT "Users"."last_login", "Users"."is_superuser", "Users"."id", "Users"."uuid", "Users"."email", "Users"."name", "Users"."password", "Users"."phone_number", "Users"."role", "Users"."last_login_at", "Users"."created_at", "Users"."updated_at" FROM "Users" WHERE "Users"."id" = 2; args=(2,)
DEBUG 2018-02-04 23:49:57,225 utils 12568 18180 (0.000) SELECT "Users"."last_login", "Users"."is_superuser", "Users"."id", "Users"."uuid", "Users"."email", "Users"."name", "Users"."password", "Users"."phone_number", "Users"."role", "Users"."last_login_at", "Users"."created_at", "Users"."updated_at" FROM "Users" WHERE "Users"."id" = 2; args=(2,)
DEBUG 2018-02-04 23:49:57,227 utils 12568 18180 (0.000) SELECT "Users"."last_login", "Users"."is_superuser", "Users"."id", "Users"."uuid", "Users"."email", "Users"."name", "Users"."password", "Users"."phone_number", "Users"."role", "Users"."last_login_at", "Users"."created_at", "Users"."updated_at" FROM "Users" WHERE "Users"."id" = 2; args=(2,)
ERROR 2018-02-04 23:49:57,228 response 12568 18180 Success
NoneType: None
INFO 2018-02-04 23:49:57,229 basehttp 12568 18180 "GET /lct_app/v1/users/2/locations HTTP/1.1" 200 1266
DEBUG 2018-02-04 23:57:22,307 utils 18896 9528 (0.000) 
            SELECT name, type FROM sqlite_master
            WHERE type in ('table', 'view') AND NOT name='sqlite_sequence'
            ORDER BY name; args=None
DEBUG 2018-02-04 23:57:22,310 utils 18896 9528 (0.000) SELECT "django_migrations"."app", "django_migrations"."name" FROM "django_migrations"; args=()
DEBUG 2018-02-04 23:57:22,535 utils 18896 6628 (0.003) SELECT "Users"."last_login", "Users"."is_superuser", "Users"."id", "Users"."uuid", "Users"."email", "Users"."name", "Users"."password", "Users"."phone_number", "Users"."role", "Users"."last_login_at", "Users"."created_at", "Users"."updated_at" FROM "Users" WHERE "Users"."email" = 'user1@gmail.com'; args=('user1@gmail.com',)
DEBUG 2018-02-04 23:57:22,539 utils 18896 6628 (0.000) SELECT "Users"."last_login", "Users"."is_superuser", "Users"."id", "Users"."uuid", "Users"."email", "Users"."name", "Users"."password", "Users"."phone_number", "Users"."role", "Users"."last_login_at", "Users"."created_at", "Users"."updated_at" FROM "Users" WHERE "Users"."id" = 2; args=(2,)
ERROR 2018-02-04 23:57:22,540 response 18896 6628 'QuerySet' object cannot be interpreted as an integer
Traceback (most recent call last):
  File "C:\Users\GS-0508\AppData\Local\Programs\Python\Python36-32\lib\site-packages\rest_framework\views.py", line 491, in dispatch
    response = handler(request, *args, **kwargs)
  File "C:\Users\GS-0508\python-projects\location_tracker\django_project\location_tracker_app\user_ops\views.py", line 53, in locations
    distance = get_distance_covered(locations)
  File "C:\Users\GS-0508\python-projects\location_tracker\django_project\location_tracker_app\utils.py", line 7, in get_distance_covered
    for i in range(locations):
TypeError: 'QuerySet' object cannot be interpreted as an integer
ERROR 2018-02-04 23:57:22,544 response 18896 6628 'QuerySet' object cannot be interpreted as an integer
INFO 2018-02-04 23:57:22,546 basehttp 18896 6628 "GET /lct_app/v1/users/2/locations HTTP/1.1" 200 123
DEBUG 2018-02-04 23:58:04,366 utils 10100 5632 (0.001) 
            SELECT name, type FROM sqlite_master
            WHERE type in ('table', 'view') AND NOT name='sqlite_sequence'
            ORDER BY name; args=None
DEBUG 2018-02-04 23:58:04,369 utils 10100 5632 (0.000) SELECT "django_migrations"."app", "django_migrations"."name" FROM "django_migrations"; args=()
DEBUG 2018-02-04 23:58:04,467 utils 10100 2368 (0.001) SELECT "Users"."last_login", "Users"."is_superuser", "Users"."id", "Users"."uuid", "Users"."email", "Users"."name", "Users"."password", "Users"."phone_number", "Users"."role", "Users"."last_login_at", "Users"."created_at", "Users"."updated_at" FROM "Users" WHERE "Users"."email" = 'user1@gmail.com'; args=('user1@gmail.com',)
DEBUG 2018-02-04 23:58:04,468 utils 10100 2368 (0.001) SELECT "Users"."last_login", "Users"."is_superuser", "Users"."id", "Users"."uuid", "Users"."email", "Users"."name", "Users"."password", "Users"."phone_number", "Users"."role", "Users"."last_login_at", "Users"."created_at", "Users"."updated_at" FROM "Users" WHERE "Users"."id" = 2; args=(2,)
DEBUG 2018-02-04 23:58:04,470 utils 10100 2368 (0.000) SELECT "Locations"."id", "Locations"."lat", "Locations"."lng", "Locations"."time", "Locations"."next_location_id", "Locations"."user_id" FROM "Locations" WHERE "Locations"."user_id" = 2; args=(2,)
DEBUG 2018-02-04 23:58:04,530 utils 10100 2368 (0.000) SELECT "Users"."last_login", "Users"."is_superuser", "Users"."id", "Users"."uuid", "Users"."email", "Users"."name", "Users"."password", "Users"."phone_number", "Users"."role", "Users"."last_login_at", "Users"."created_at", "Users"."updated_at" FROM "Users" WHERE "Users"."id" = 2; args=(2,)
DEBUG 2018-02-04 23:58:04,535 utils 10100 2368 (0.000) SELECT "Users"."last_login", "Users"."is_superuser", "Users"."id", "Users"."uuid", "Users"."email", "Users"."name", "Users"."password", "Users"."phone_number", "Users"."role", "Users"."last_login_at", "Users"."created_at", "Users"."updated_at" FROM "Users" WHERE "Users"."id" = 2; args=(2,)
DEBUG 2018-02-04 23:58:04,537 utils 10100 2368 (0.001) SELECT "Users"."last_login", "Users"."is_superuser", "Users"."id", "Users"."uuid", "Users"."email", "Users"."name", "Users"."password", "Users"."phone_number", "Users"."role", "Users"."last_login_at", "Users"."created_at", "Users"."updated_at" FROM "Users" WHERE "Users"."id" = 2; args=(2,)
ERROR 2018-02-04 23:58:04,537 response 10100 2368 Success
NoneType: None
INFO 2018-02-04 23:58:04,538 basehttp 10100 2368 "GET /lct_app/v1/users/2/locations HTTP/1.1" 200 1282
DEBUG 2018-02-04 23:58:41,377 utils 17620 16848 (0.002) 
            SELECT name, type FROM sqlite_master
            WHERE type in ('table', 'view') AND NOT name='sqlite_sequence'
            ORDER BY name; args=None
DEBUG 2018-02-04 23:58:41,380 utils 17620 16848 (0.000) SELECT "django_migrations"."app", "django_migrations"."name" FROM "django_migrations"; args=()
DEBUG 2018-02-04 23:58:41,682 utils 17620 12008 (0.005) SELECT "Users"."last_login", "Users"."is_superuser", "Users"."id", "Users"."uuid", "Users"."email", "Users"."name", "Users"."password", "Users"."phone_number", "Users"."role", "Users"."last_login_at", "Users"."created_at", "Users"."updated_at" FROM "Users" WHERE "Users"."email" = 'user1@gmail.com'; args=('user1@gmail.com',)
DEBUG 2018-02-04 23:58:41,687 utils 17620 12008 (0.001) SELECT "Users"."last_login", "Users"."is_superuser", "Users"."id", "Users"."uuid", "Users"."email", "Users"."name", "Users"."password", "Users"."phone_number", "Users"."role", "Users"."last_login_at", "Users"."created_at", "Users"."updated_at" FROM "Users" WHERE "Users"."id" = 2; args=(2,)
DEBUG 2018-02-04 23:58:41,692 utils 17620 12008 (0.001) SELECT "Locations"."id", "Locations"."lat", "Locations"."lng", "Locations"."time", "Locations"."next_location_id", "Locations"."user_id" FROM "Locations" WHERE "Locations"."user_id" = 2; args=(2,)
DEBUG 2018-02-04 23:58:41,707 utils 17620 12008 (0.000) SELECT "Users"."last_login", "Users"."is_superuser", "Users"."id", "Users"."uuid", "Users"."email", "Users"."name", "Users"."password", "Users"."phone_number", "Users"."role", "Users"."last_login_at", "Users"."created_at", "Users"."updated_at" FROM "Users" WHERE "Users"."id" = 2; args=(2,)
DEBUG 2018-02-04 23:58:41,712 utils 17620 12008 (0.001) SELECT "Users"."last_login", "Users"."is_superuser", "Users"."id", "Users"."uuid", "Users"."email", "Users"."name", "Users"."password", "Users"."phone_number", "Users"."role", "Users"."last_login_at", "Users"."created_at", "Users"."updated_at" FROM "Users" WHERE "Users"."id" = 2; args=(2,)
DEBUG 2018-02-04 23:58:41,715 utils 17620 12008 (0.000) SELECT "Users"."last_login", "Users"."is_superuser", "Users"."id", "Users"."uuid", "Users"."email", "Users"."name", "Users"."password", "Users"."phone_number", "Users"."role", "Users"."last_login_at", "Users"."created_at", "Users"."updated_at" FROM "Users" WHERE "Users"."id" = 2; args=(2,)
ERROR 2018-02-04 23:58:41,716 response 17620 12008 Success
NoneType: None
INFO 2018-02-04 23:58:41,717 basehttp 17620 12008 "GET /lct_app/v1/users/2/locations HTTP/1.1" 200 1280
DEBUG 2018-02-04 23:58:44,460 utils 17620 18064 (0.003) SELECT "Users"."last_login", "Users"."is_superuser", "Users"."id", "Users"."uuid", "Users"."email", "Users"."name", "Users"."password", "Users"."phone_number", "Users"."role", "Users"."last_login_at", "Users"."created_at", "Users"."updated_at" FROM "Users" WHERE "Users"."email" = 'user1@gmail.com'; args=('user1@gmail.com',)
DEBUG 2018-02-04 23:58:44,465 utils 17620 18064 (0.001) SELECT "Users"."last_login", "Users"."is_superuser", "Users"."id", "Users"."uuid", "Users"."email", "Users"."name", "Users"."password", "Users"."phone_number", "Users"."role", "Users"."last_login_at", "Users"."created_at", "Users"."updated_at" FROM "Users" WHERE "Users"."id" = 2; args=(2,)
DEBUG 2018-02-04 23:58:44,469 utils 17620 18064 (0.001) SELECT "Locations"."id", "Locations"."lat", "Locations"."lng", "Locations"."time", "Locations"."next_location_id", "Locations"."user_id" FROM "Locations" WHERE "Locations"."user_id" = 2; args=(2,)
DEBUG 2018-02-04 23:58:44,475 utils 17620 18064 (0.000) SELECT "Users"."last_login", "Users"."is_superuser", "Users"."id", "Users"."uuid", "Users"."email", "Users"."name", "Users"."password", "Users"."phone_number", "Users"."role", "Users"."last_login_at", "Users"."created_at", "Users"."updated_at" FROM "Users" WHERE "Users"."id" = 2; args=(2,)
DEBUG 2018-02-04 23:58:44,482 utils 17620 18064 (0.001) SELECT "Users"."last_login", "Users"."is_superuser", "Users"."id", "Users"."uuid", "Users"."email", "Users"."name", "Users"."password", "Users"."phone_number", "Users"."role", "Users"."last_login_at", "Users"."created_at", "Users"."updated_at" FROM "Users" WHERE "Users"."id" = 2; args=(2,)
DEBUG 2018-02-04 23:58:44,486 utils 17620 18064 (0.000) SELECT "Users"."last_login", "Users"."is_superuser", "Users"."id", "Users"."uuid", "Users"."email", "Users"."name", "Users"."password", "Users"."phone_number", "Users"."role", "Users"."last_login_at", "Users"."created_at", "Users"."updated_at" FROM "Users" WHERE "Users"."id" = 2; args=(2,)
ERROR 2018-02-04 23:58:44,488 response 17620 18064 Success
NoneType: None
INFO 2018-02-04 23:58:44,490 basehttp 17620 18064 "GET /lct_app/v1/users/2/locations HTTP/1.1" 200 1280
DEBUG 2018-02-04 23:58:51,131 utils 17620 7432 (0.000) SELECT "Users"."last_login", "Users"."is_superuser", "Users"."id", "Users"."uuid", "Users"."email", "Users"."name", "Users"."password", "Users"."phone_number", "Users"."role", "Users"."last_login_at", "Users"."created_at", "Users"."updated_at" FROM "Users" WHERE "Users"."email" = 'user1@gmail.com'; args=('user1@gmail.com',)
DEBUG 2018-02-04 23:58:51,133 utils 17620 7432 (0.000) SELECT "Users"."last_login", "Users"."is_superuser", "Users"."id", "Users"."uuid", "Users"."email", "Users"."name", "Users"."password", "Users"."phone_number", "Users"."role", "Users"."last_login_at", "Users"."created_at", "Users"."updated_at" FROM "Users" WHERE "Users"."id" = 2; args=(2,)
DEBUG 2018-02-04 23:58:51,134 utils 17620 7432 (0.000) SELECT "Locations"."id", "Locations"."lat", "Locations"."lng", "Locations"."time", "Locations"."next_location_id", "Locations"."user_id" FROM "Locations" WHERE "Locations"."user_id" = 2; args=(2,)
DEBUG 2018-02-04 23:58:51,136 utils 17620 7432 (0.001) SELECT "Users"."last_login", "Users"."is_superuser", "Users"."id", "Users"."uuid", "Users"."email", "Users"."name", "Users"."password", "Users"."phone_number", "Users"."role", "Users"."last_login_at", "Users"."created_at", "Users"."updated_at" FROM "Users" WHERE "Users"."id" = 2; args=(2,)
DEBUG 2018-02-04 23:58:51,139 utils 17620 7432 (0.000) SELECT "Users"."last_login", "Users"."is_superuser", "Users"."id", "Users"."uuid", "Users"."email", "Users"."name", "Users"."password", "Users"."phone_number", "Users"."role", "Users"."last_login_at", "Users"."created_at", "Users"."updated_at" FROM "Users" WHERE "Users"."id" = 2; args=(2,)
DEBUG 2018-02-04 23:58:51,141 utils 17620 7432 (0.000) SELECT "Users"."last_login", "Users"."is_superuser", "Users"."id", "Users"."uuid", "Users"."email", "Users"."name", "Users"."password", "Users"."phone_number", "Users"."role", "Users"."last_login_at", "Users"."created_at", "Users"."updated_at" FROM "Users" WHERE "Users"."id" = 2; args=(2,)
ERROR 2018-02-04 23:58:51,142 response 17620 7432 Success
NoneType: None
INFO 2018-02-04 23:58:51,143 basehttp 17620 7432 "GET /lct_app/v1/users/2/locations HTTP/1.1" 200 1280
DEBUG 2018-02-04 23:58:53,643 utils 19776 19376 (0.000) 
            SELECT name, type FROM sqlite_master
            WHERE type in ('table', 'view') AND NOT name='sqlite_sequence'
            ORDER BY name; args=None
DEBUG 2018-02-04 23:58:53,646 utils 19776 19376 (0.000) SELECT "django_migrations"."app", "django_migrations"."name" FROM "django_migrations"; args=()
DEBUG 2018-02-04 23:58:53,772 utils 19776 2068 (0.001) SELECT "Users"."last_login", "Users"."is_superuser", "Users"."id", "Users"."uuid", "Users"."email", "Users"."name", "Users"."password", "Users"."phone_number", "Users"."role", "Users"."last_login_at", "Users"."created_at", "Users"."updated_at" FROM "Users" WHERE "Users"."email" = 'user1@gmail.com'; args=('user1@gmail.com',)
DEBUG 2018-02-04 23:58:53,774 utils 19776 2068 (0.000) SELECT "Users"."last_login", "Users"."is_superuser", "Users"."id", "Users"."uuid", "Users"."email", "Users"."name", "Users"."password", "Users"."phone_number", "Users"."role", "Users"."last_login_at", "Users"."created_at", "Users"."updated_at" FROM "Users" WHERE "Users"."id" = 2; args=(2,)
DEBUG 2018-02-04 23:58:53,775 utils 19776 2068 (0.000) SELECT "Locations"."id", "Locations"."lat", "Locations"."lng", "Locations"."time", "Locations"."next_location_id", "Locations"."user_id" FROM "Locations" WHERE "Locations"."user_id" = 2; args=(2,)
DEBUG 2018-02-04 23:58:53,778 utils 19776 2068 (0.000) SELECT "Users"."last_login", "Users"."is_superuser", "Users"."id", "Users"."uuid", "Users"."email", "Users"."name", "Users"."password", "Users"."phone_number", "Users"."role", "Users"."last_login_at", "Users"."created_at", "Users"."updated_at" FROM "Users" WHERE "Users"."id" = 2; args=(2,)
DEBUG 2018-02-04 23:58:53,781 utils 19776 2068 (0.000) SELECT "Users"."last_login", "Users"."is_superuser", "Users"."id", "Users"."uuid", "Users"."email", "Users"."name", "Users"."password", "Users"."phone_number", "Users"."role", "Users"."last_login_at", "Users"."created_at", "Users"."updated_at" FROM "Users" WHERE "Users"."id" = 2; args=(2,)
DEBUG 2018-02-04 23:58:53,782 utils 19776 2068 (0.000) SELECT "Users"."last_login", "Users"."is_superuser", "Users"."id", "Users"."uuid", "Users"."email", "Users"."name", "Users"."password", "Users"."phone_number", "Users"."role", "Users"."last_login_at", "Users"."created_at", "Users"."updated_at" FROM "Users" WHERE "Users"."id" = 2; args=(2,)
ERROR 2018-02-04 23:58:53,783 response 19776 2068 Success
NoneType: None
INFO 2018-02-04 23:58:53,784 basehttp 19776 2068 "GET /lct_app/v1/users/2/locations HTTP/1.1" 200 1280
DEBUG 2018-02-04 23:59:04,545 utils 16044 19132 (0.001) 
            SELECT name, type FROM sqlite_master
            WHERE type in ('table', 'view') AND NOT name='sqlite_sequence'
            ORDER BY name; args=None
DEBUG 2018-02-04 23:59:04,548 utils 16044 19132 (0.000) SELECT "django_migrations"."app", "django_migrations"."name" FROM "django_migrations"; args=()
DEBUG 2018-02-04 23:59:05,146 utils 16044 13812 (0.001) SELECT "Users"."last_login", "Users"."is_superuser", "Users"."id", "Users"."uuid", "Users"."email", "Users"."name", "Users"."password", "Users"."phone_number", "Users"."role", "Users"."last_login_at", "Users"."created_at", "Users"."updated_at" FROM "Users" WHERE "Users"."email" = 'user1@gmail.com'; args=('user1@gmail.com',)
DEBUG 2018-02-04 23:59:05,147 utils 16044 13812 (0.000) SELECT "Users"."last_login", "Users"."is_superuser", "Users"."id", "Users"."uuid", "Users"."email", "Users"."name", "Users"."password", "Users"."phone_number", "Users"."role", "Users"."last_login_at", "Users"."created_at", "Users"."updated_at" FROM "Users" WHERE "Users"."id" = 2; args=(2,)
DEBUG 2018-02-04 23:59:05,149 utils 16044 13812 (0.000) SELECT "Locations"."id", "Locations"."lat", "Locations"."lng", "Locations"."time", "Locations"."next_location_id", "Locations"."user_id" FROM "Locations" WHERE "Locations"."user_id" = 2; args=(2,)
DEBUG 2018-02-04 23:59:05,152 utils 16044 13812 (0.000) SELECT "Users"."last_login", "Users"."is_superuser", "Users"."id", "Users"."uuid", "Users"."email", "Users"."name", "Users"."password", "Users"."phone_number", "Users"."role", "Users"."last_login_at", "Users"."created_at", "Users"."updated_at" FROM "Users" WHERE "Users"."id" = 2; args=(2,)
DEBUG 2018-02-04 23:59:05,156 utils 16044 13812 (0.000) SELECT "Users"."last_login", "Users"."is_superuser", "Users"."id", "Users"."uuid", "Users"."email", "Users"."name", "Users"."password", "Users"."phone_number", "Users"."role", "Users"."last_login_at", "Users"."created_at", "Users"."updated_at" FROM "Users" WHERE "Users"."id" = 2; args=(2,)
DEBUG 2018-02-04 23:59:05,157 utils 16044 13812 (0.000) SELECT "Users"."last_login", "Users"."is_superuser", "Users"."id", "Users"."uuid", "Users"."email", "Users"."name", "Users"."password", "Users"."phone_number", "Users"."role", "Users"."last_login_at", "Users"."created_at", "Users"."updated_at" FROM "Users" WHERE "Users"."id" = 2; args=(2,)
ERROR 2018-02-04 23:59:05,158 response 16044 13812 Success
NoneType: None
INFO 2018-02-04 23:59:05,159 basehttp 16044 13812 "GET /lct_app/v1/users/2/locations HTTP/1.1" 200 1280
DEBUG 2018-02-04 23:59:49,719 utils 19804 18504 (0.000) 
            SELECT name, type FROM sqlite_master
            WHERE type in ('table', 'view') AND NOT name='sqlite_sequence'
            ORDER BY name; args=None
DEBUG 2018-02-04 23:59:49,722 utils 19804 18504 (0.000) SELECT "django_migrations"."app", "django_migrations"."name" FROM "django_migrations"; args=()
DEBUG 2018-02-04 23:59:50,114 utils 19804 20328 (0.001) SELECT "Users"."last_login", "Users"."is_superuser", "Users"."id", "Users"."uuid", "Users"."email", "Users"."name", "Users"."password", "Users"."phone_number", "Users"."role", "Users"."last_login_at", "Users"."created_at", "Users"."updated_at" FROM "Users" WHERE "Users"."email" = 'user1@gmail.com'; args=('user1@gmail.com',)
DEBUG 2018-02-04 23:59:50,116 utils 19804 20328 (0.001) SELECT "Users"."last_login", "Users"."is_superuser", "Users"."id", "Users"."uuid", "Users"."email", "Users"."name", "Users"."password", "Users"."phone_number", "Users"."role", "Users"."last_login_at", "Users"."created_at", "Users"."updated_at" FROM "Users" WHERE "Users"."id" = 2; args=(2,)
DEBUG 2018-02-04 23:59:50,119 utils 19804 20328 (0.000) SELECT "Locations"."id", "Locations"."lat", "Locations"."lng", "Locations"."time", "Locations"."next_location_id", "Locations"."user_id" FROM "Locations" WHERE "Locations"."user_id" = 2; args=(2,)
DEBUG 2018-02-04 23:59:50,125 utils 19804 20328 (0.000) SELECT "Users"."last_login", "Users"."is_superuser", "Users"."id", "Users"."uuid", "Users"."email", "Users"."name", "Users"."password", "Users"."phone_number", "Users"."role", "Users"."last_login_at", "Users"."created_at", "Users"."updated_at" FROM "Users" WHERE "Users"."id" = 2; args=(2,)
DEBUG 2018-02-04 23:59:50,130 utils 19804 20328 (0.000) SELECT "Users"."last_login", "Users"."is_superuser", "Users"."id", "Users"."uuid", "Users"."email", "Users"."name", "Users"."password", "Users"."phone_number", "Users"."role", "Users"."last_login_at", "Users"."created_at", "Users"."updated_at" FROM "Users" WHERE "Users"."id" = 2; args=(2,)
DEBUG 2018-02-04 23:59:50,133 utils 19804 20328 (0.000) SELECT "Users"."last_login", "Users"."is_superuser", "Users"."id", "Users"."uuid", "Users"."email", "Users"."name", "Users"."password", "Users"."phone_number", "Users"."role", "Users"."last_login_at", "Users"."created_at", "Users"."updated_at" FROM "Users" WHERE "Users"."id" = 2; args=(2,)
ERROR 2018-02-04 23:59:50,134 response 19804 20328 Success
NoneType: None
INFO 2018-02-04 23:59:50,135 basehttp 19804 20328 "GET /lct_app/v1/users/2/locations HTTP/1.1" 200 1278
DEBUG 2018-02-05 00:00:00,972 utils 19804 11996 (0.001) SELECT "django_session"."session_key", "django_session"."session_data", "django_session"."expire_date" FROM "django_session" WHERE ("django_session"."session_key" = 'mz66yltn6yeqmst7fuv6sswequ3rajge' AND "django_session"."expire_date" > '2018-02-04 18:30:00.968161'); args=('mz66yltn6yeqmst7fuv6sswequ3rajge', '2018-02-04 18:30:00.968161')
DEBUG 2018-02-05 00:00:00,974 utils 19804 11996 (0.000) SELECT "Users"."last_login", "Users"."is_superuser", "Users"."id", "Users"."uuid", "Users"."email", "Users"."name", "Users"."password", "Users"."phone_number", "Users"."role", "Users"."last_login_at", "Users"."created_at", "Users"."updated_at" FROM "Users" WHERE "Users"."id" = 1; args=(1,)
DEBUG 2018-02-05 00:00:00,976 utils 19804 11996 (0.000) SELECT COUNT(*) AS "__count" FROM "Locations"; args=()
DEBUG 2018-02-05 00:00:00,977 utils 19804 11996 (0.000) SELECT COUNT(*) AS "__count" FROM "Locations"; args=()
DEBUG 2018-02-05 00:00:01,000 utils 19804 11996 (0.001) SELECT "Locations"."id", "Locations"."lat", "Locations"."lng", "Locations"."time", "Locations"."next_location_id", "Locations"."user_id" FROM "Locations" ORDER BY "Locations"."id" DESC; args=()
DEBUG 2018-02-05 00:00:01,027 base 19804 11996 Exception while resolving variable 'errors' in template 'admin/change_list.html'.
Traceback (most recent call last):
  File "C:\Users\GS-0508\AppData\Local\Programs\Python\Python36-32\lib\site-packages\django\template\base.py", line 882, in _resolve_lookup
    current = current[bit]
TypeError: 'NoneType' object is not subscriptable

During handling of the above exception, another exception occurred:

Traceback (most recent call last):
  File "C:\Users\GS-0508\AppData\Local\Programs\Python\Python36-32\lib\site-packages\django\template\base.py", line 890, in _resolve_lookup
    current = getattr(current, bit)
AttributeError: 'NoneType' object has no attribute 'errors'

During handling of the above exception, another exception occurred:

Traceback (most recent call last):
  File "C:\Users\GS-0508\AppData\Local\Programs\Python\Python36-32\lib\site-packages\django\template\base.py", line 896, in _resolve_lookup
    current = current[int(bit)]
ValueError: invalid literal for int() with base 10: 'errors'

During handling of the above exception, another exception occurred:

Traceback (most recent call last):
  File "C:\Users\GS-0508\AppData\Local\Programs\Python\Python36-32\lib\site-packages\django\template\base.py", line 903, in _resolve_lookup
    (bit, current))  # missing attribute
django.template.base.VariableDoesNotExist: Failed lookup for key [errors] in 'None'
DEBUG 2018-02-05 00:00:01,031 base 19804 11996 Exception while resolving variable 'show' in template 'admin/change_list.html'.
Traceback (most recent call last):
  File "C:\Users\GS-0508\AppData\Local\Programs\Python\Python36-32\lib\site-packages\django\template\base.py", line 882, in _resolve_lookup
    current = current[bit]
  File "C:\Users\GS-0508\AppData\Local\Programs\Python\Python36-32\lib\site-packages\django\template\context.py", line 87, in __getitem__
    raise KeyError(key)
KeyError: 'show'

During handling of the above exception, another exception occurred:

Traceback (most recent call last):
  File "C:\Users\GS-0508\AppData\Local\Programs\Python\Python36-32\lib\site-packages\django\template\base.py", line 888, in _resolve_lookup
    if isinstance(current, BaseContext) and getattr(type(current), bit):
AttributeError: type object 'RequestContext' has no attribute 'show'

During handling of the above exception, another exception occurred:

Traceback (most recent call last):
  File "C:\Users\GS-0508\AppData\Local\Programs\Python\Python36-32\lib\site-packages\django\template\base.py", line 896, in _resolve_lookup
    current = current[int(bit)]
ValueError: invalid literal for int() with base 10: 'show'

During handling of the above exception, another exception occurred:

Traceback (most recent call last):
  File "C:\Users\GS-0508\AppData\Local\Programs\Python\Python36-32\lib\site-packages\django\template\base.py", line 903, in _resolve_lookup
    (bit, current))  # missing attribute
django.template.base.VariableDoesNotExist: Failed lookup for key [show] in "[{'True': True, 'False': False, 'None': None, 'csrf_token': <SimpleLazyObject: <function csrf.<locals>._get_val at 0x04B0B7C8>>}]"
DEBUG 2018-02-05 00:00:01,032 base 19804 11996 Exception while resolving variable 'is_multipart' in template 'admin/change_list.html'.
Traceback (most recent call last):
  File "C:\Users\GS-0508\AppData\Local\Programs\Python\Python36-32\lib\site-packages\django\template\base.py", line 882, in _resolve_lookup
    current = current[bit]
TypeError: 'NoneType' object is not subscriptable

During handling of the above exception, another exception occurred:

Traceback (most recent call last):
  File "C:\Users\GS-0508\AppData\Local\Programs\Python\Python36-32\lib\site-packages\django\template\base.py", line 890, in _resolve_lookup
    current = getattr(current, bit)
AttributeError: 'NoneType' object has no attribute 'is_multipart'

During handling of the above exception, another exception occurred:

Traceback (most recent call last):
  File "C:\Users\GS-0508\AppData\Local\Programs\Python\Python36-32\lib\site-packages\django\template\base.py", line 896, in _resolve_lookup
    current = current[int(bit)]
ValueError: invalid literal for int() with base 10: 'is_multipart'

During handling of the above exception, another exception occurred:

Traceback (most recent call last):
  File "C:\Users\GS-0508\AppData\Local\Programs\Python\Python36-32\lib\site-packages\django\template\base.py", line 903, in _resolve_lookup
    (bit, current))  # missing attribute
django.template.base.VariableDoesNotExist: Failed lookup for key [is_multipart] in 'None'
DEBUG 2018-02-05 00:00:01,056 base 19804 11996 Exception while resolving variable 'non_field_errors' in template 'admin/change_list.html'.
Traceback (most recent call last):
  File "C:\Users\GS-0508\AppData\Local\Programs\Python\Python36-32\lib\site-packages\django\template\base.py", line 882, in _resolve_lookup
    current = current[bit]
TypeError: 'NoneType' object is not subscriptable

During handling of the above exception, another exception occurred:

Traceback (most recent call last):
  File "C:\Users\GS-0508\AppData\Local\Programs\Python\Python36-32\lib\site-packages\django\template\base.py", line 890, in _resolve_lookup
    current = getattr(current, bit)
AttributeError: 'NoneType' object has no attribute 'non_field_errors'

During handling of the above exception, another exception occurred:

Traceback (most recent call last):
  File "C:\Users\GS-0508\AppData\Local\Programs\Python\Python36-32\lib\site-packages\django\template\base.py", line 896, in _resolve_lookup
    current = current[int(bit)]
ValueError: invalid literal for int() with base 10: 'non_field_errors'

During handling of the above exception, another exception occurred:

Traceback (most recent call last):
  File "C:\Users\GS-0508\AppData\Local\Programs\Python\Python36-32\lib\site-packages\django\template\base.py", line 903, in _resolve_lookup
    (bit, current))  # missing attribute
django.template.base.VariableDoesNotExist: Failed lookup for key [non_field_errors] in 'None'
DEBUG 2018-02-05 00:00:01,057 base 19804 11996 Exception while resolving variable 'non_field_errors' in template 'admin/change_list.html'.
Traceback (most recent call last):
  File "C:\Users\GS-0508\AppData\Local\Programs\Python\Python36-32\lib\site-packages\django\template\base.py", line 882, in _resolve_lookup
    current = current[bit]
TypeError: 'NoneType' object is not subscriptable

During handling of the above exception, another exception occurred:

Traceback (most recent call last):
  File "C:\Users\GS-0508\AppData\Local\Programs\Python\Python36-32\lib\site-packages\django\template\base.py", line 890, in _resolve_lookup
    current = getattr(current, bit)
AttributeError: 'NoneType' object has no attribute 'non_field_errors'

During handling of the above exception, another exception occurred:

Traceback (most recent call last):
  File "C:\Users\GS-0508\AppData\Local\Programs\Python\Python36-32\lib\site-packages\django\template\base.py", line 896, in _resolve_lookup
    current = current[int(bit)]
ValueError: invalid literal for int() with base 10: 'non_field_errors'

During handling of the above exception, another exception occurred:

Traceback (most recent call last):
  File "C:\Users\GS-0508\AppData\Local\Programs\Python\Python36-32\lib\site-packages\django\template\base.py", line 903, in _resolve_lookup
    (bit, current))  # missing attribute
django.template.base.VariableDoesNotExist: Failed lookup for key [non_field_errors] in 'None'
DEBUG 2018-02-05 00:00:01,058 base 19804 11996 Exception while resolving variable 'non_field_errors' in template 'admin/change_list.html'.
Traceback (most recent call last):
  File "C:\Users\GS-0508\AppData\Local\Programs\Python\Python36-32\lib\site-packages\django\template\base.py", line 882, in _resolve_lookup
    current = current[bit]
TypeError: 'NoneType' object is not subscriptable

During handling of the above exception, another exception occurred:

Traceback (most recent call last):
  File "C:\Users\GS-0508\AppData\Local\Programs\Python\Python36-32\lib\site-packages\django\template\base.py", line 890, in _resolve_lookup
    current = getattr(current, bit)
AttributeError: 'NoneType' object has no attribute 'non_field_errors'

During handling of the above exception, another exception occurred:

Traceback (most recent call last):
  File "C:\Users\GS-0508\AppData\Local\Programs\Python\Python36-32\lib\site-packages\django\template\base.py", line 896, in _resolve_lookup
    current = current[int(bit)]
ValueError: invalid literal for int() with base 10: 'non_field_errors'

During handling of the above exception, another exception occurred:

Traceback (most recent call last):
  File "C:\Users\GS-0508\AppData\Local\Programs\Python\Python36-32\lib\site-packages\django\template\base.py", line 903, in _resolve_lookup
    (bit, current))  # missing attribute
django.template.base.VariableDoesNotExist: Failed lookup for key [non_field_errors] in 'None'
INFO 2018-02-05 00:00:01,061 basehttp 19804 11996 "GET /admin/location_tracker_app/location/ HTTP/1.1" 200 4777
DEBUG 2018-02-05 00:00:01,102 utils 19804 19692 (0.001) SELECT "django_session"."session_key", "django_session"."session_data", "django_session"."expire_date" FROM "django_session" WHERE ("django_session"."session_key" = 'mz66yltn6yeqmst7fuv6sswequ3rajge' AND "django_session"."expire_date" > '2018-02-04 18:30:01.098661'); args=('mz66yltn6yeqmst7fuv6sswequ3rajge', '2018-02-04 18:30:01.098661')
DEBUG 2018-02-05 00:00:01,105 utils 19804 19692 (0.001) SELECT "Users"."last_login", "Users"."is_superuser", "Users"."id", "Users"."uuid", "Users"."email", "Users"."name", "Users"."password", "Users"."phone_number", "Users"."role", "Users"."last_login_at", "Users"."created_at", "Users"."updated_at" FROM "Users" WHERE "Users"."id" = 1; args=(1,)
INFO 2018-02-05 00:00:01,108 basehttp 19804 19692 "GET /admin/jsi18n/ HTTP/1.1" 200 3189
DEBUG 2018-02-05 00:00:03,980 utils 19804 17984 (0.001) SELECT "django_session"."session_key", "django_session"."session_data", "django_session"."expire_date" FROM "django_session" WHERE ("django_session"."session_key" = 'mz66yltn6yeqmst7fuv6sswequ3rajge' AND "django_session"."expire_date" > '2018-02-04 18:30:03.976161'); args=('mz66yltn6yeqmst7fuv6sswequ3rajge', '2018-02-04 18:30:03.976161')
DEBUG 2018-02-05 00:00:03,982 utils 19804 17984 (0.000) SELECT "Users"."last_login", "Users"."is_superuser", "Users"."id", "Users"."uuid", "Users"."email", "Users"."name", "Users"."password", "Users"."phone_number", "Users"."role", "Users"."last_login_at", "Users"."created_at", "Users"."updated_at" FROM "Users" WHERE "Users"."id" = 1; args=(1,)
DEBUG 2018-02-05 00:00:03,983 utils 19804 17984 (0.000) BEGIN; args=None
DEBUG 2018-02-05 00:00:03,985 utils 19804 17984 (0.000) SELECT "Locations"."id", "Locations"."lat", "Locations"."lng", "Locations"."time", "Locations"."next_location_id", "Locations"."user_id" FROM "Locations" WHERE "Locations"."id" = 17; args=(17,)
DEBUG 2018-02-05 00:00:04,001 utils 19804 17984 (0.000) SELECT "django_content_type"."id", "django_content_type"."app_label", "django_content_type"."model" FROM "django_content_type" WHERE ("django_content_type"."app_label" = 'location_tracker_app' AND "django_content_type"."model" = 'location'); args=('location_tracker_app', 'location')
DEBUG 2018-02-05 00:00:04,088 utils 19804 17984 (0.001) SELECT "Locations"."id", "Locations"."lat", "Locations"."lng", "Locations"."time", "Locations"."next_location_id", "Locations"."user_id" FROM "Locations"; args=()
DEBUG 2018-02-05 00:00:04,100 base 19804 17984 Exception while resolving variable 'can_delete_related' in template 'admin/widgets/related_widget_wrapper.html'.
Traceback (most recent call last):
  File "C:\Users\GS-0508\AppData\Local\Programs\Python\Python36-32\lib\site-packages\django\template\base.py", line 882, in _resolve_lookup
    current = current[bit]
  File "C:\Users\GS-0508\AppData\Local\Programs\Python\Python36-32\lib\site-packages\django\template\context.py", line 87, in __getitem__
    raise KeyError(key)
KeyError: 'can_delete_related'

During handling of the above exception, another exception occurred:

Traceback (most recent call last):
  File "C:\Users\GS-0508\AppData\Local\Programs\Python\Python36-32\lib\site-packages\django\template\base.py", line 888, in _resolve_lookup
    if isinstance(current, BaseContext) and getattr(type(current), bit):
AttributeError: type object 'Context' has no attribute 'can_delete_related'

During handling of the above exception, another exception occurred:

Traceback (most recent call last):
  File "C:\Users\GS-0508\AppData\Local\Programs\Python\Python36-32\lib\site-packages\django\template\base.py", line 896, in _resolve_lookup
    current = current[int(bit)]
ValueError: invalid literal for int() with base 10: 'can_delete_related'

During handling of the above exception, another exception occurred:

Traceback (most recent call last):
  File "C:\Users\GS-0508\AppData\Local\Programs\Python\Python36-32\lib\site-packages\django\template\base.py", line 903, in _resolve_lookup
    (bit, current))  # missing attribute
django.template.base.VariableDoesNotExist: Failed lookup for key [can_delete_related] in '[{\'True\': True, \'False\': False, \'None\': None}, {\'rendered_widget\': \'<select name="next_location" id="id_next_location">\\n  <option value="" selected>---------</option>\\n\\n  <option value="15">Location object</option>\\n\\n  <option value="16">Location object</option>\\n\\n  <option value="17">Location object</option>\\n\\n</select>\', \'name\': \'next_location\', \'url_params\': \'_to_field=id&_popup=1\', \'model\': \'location\', \'can_change_related\': True, \'change_related_template_url\': \'/admin/location_tracker_app/location/__fk__/change/\', \'can_add_related\': True, \'add_related_url\': \'/admin/location_tracker_app/location/add/\'}, {\'block\': <Block Node: links. Contents: [<TextNode: \'\\n        \'>, <django.template.defaulttags.SpacelessNode object at 0x04BA65B0>, <TextNode: \'\\n    \'>]>}]'
DEBUG 2018-02-05 00:00:04,103 utils 19804 17984 (0.000) SELECT "Users"."last_login", "Users"."is_superuser", "Users"."id", "Users"."uuid", "Users"."email", "Users"."name", "Users"."password", "Users"."phone_number", "Users"."role", "Users"."last_login_at", "Users"."created_at", "Users"."updated_at" FROM "Users"; args=()
DEBUG 2018-02-05 00:00:04,120 base 19804 17984 Exception while resolving variable 'can_delete_related' in template 'admin/widgets/related_widget_wrapper.html'.
Traceback (most recent call last):
  File "C:\Users\GS-0508\AppData\Local\Programs\Python\Python36-32\lib\site-packages\django\template\base.py", line 882, in _resolve_lookup
    current = current[bit]
  File "C:\Users\GS-0508\AppData\Local\Programs\Python\Python36-32\lib\site-packages\django\template\context.py", line 87, in __getitem__
    raise KeyError(key)
KeyError: 'can_delete_related'

During handling of the above exception, another exception occurred:

Traceback (most recent call last):
  File "C:\Users\GS-0508\AppData\Local\Programs\Python\Python36-32\lib\site-packages\django\template\base.py", line 888, in _resolve_lookup
    if isinstance(current, BaseContext) and getattr(type(current), bit):
AttributeError: type object 'Context' has no attribute 'can_delete_related'

During handling of the above exception, another exception occurred:

Traceback (most recent call last):
  File "C:\Users\GS-0508\AppData\Local\Programs\Python\Python36-32\lib\site-packages\django\template\base.py", line 896, in _resolve_lookup
    current = current[int(bit)]
ValueError: invalid literal for int() with base 10: 'can_delete_related'

During handling of the above exception, another exception occurred:

Traceback (most recent call last):
  File "C:\Users\GS-0508\AppData\Local\Programs\Python\Python36-32\lib\site-packages\django\template\base.py", line 903, in _resolve_lookup
    (bit, current))  # missing attribute
django.template.base.VariableDoesNotExist: Failed lookup for key [can_delete_related] in '[{\'True\': True, \'False\': False, \'None\': None}, {\'rendered_widget\': \'<select name="user" required id="id_user">\\n  <option value="">---------</option>\\n\\n  <option value="1">admin@lct.com</option>\\n\\n  <option value="2" selected>user1@gmail.com</option>\\n\\n</select>\', \'name\': \'user\', \'url_params\': \'_to_field=id&_popup=1\', \'model\': \'user\', \'can_change_related\': True, \'change_related_template_url\': \'/admin/location_tracker_app/user/__fk__/change/\', \'can_add_related\': True, \'add_related_url\': \'/admin/location_tracker_app/user/add/\'}, {\'block\': <Block Node: links. Contents: [<TextNode: \'\\n        \'>, <django.template.defaulttags.SpacelessNode object at 0x04BA6BF0>, <TextNode: \'\\n    \'>]>}]'
INFO 2018-02-05 00:00:04,129 basehttp 19804 17984 "GET /admin/location_tracker_app/location/17/change/ HTTP/1.1" 200 8055
DEBUG 2018-02-05 00:00:04,173 utils 19804 18720 (0.002) SELECT "django_session"."session_key", "django_session"."session_data", "django_session"."expire_date" FROM "django_session" WHERE ("django_session"."session_key" = 'mz66yltn6yeqmst7fuv6sswequ3rajge' AND "django_session"."expire_date" > '2018-02-04 18:30:04.169661'); args=('mz66yltn6yeqmst7fuv6sswequ3rajge', '2018-02-04 18:30:04.169661')
DEBUG 2018-02-05 00:00:04,176 utils 19804 18720 (0.000) SELECT "Users"."last_login", "Users"."is_superuser", "Users"."id", "Users"."uuid", "Users"."email", "Users"."name", "Users"."password", "Users"."phone_number", "Users"."role", "Users"."last_login_at", "Users"."created_at", "Users"."updated_at" FROM "Users" WHERE "Users"."id" = 1; args=(1,)
INFO 2018-02-05 00:00:04,179 basehttp 19804 18720 "GET /admin/jsi18n/ HTTP/1.1" 200 3189
DEBUG 2018-02-05 00:00:35,672 utils 19804 4864 (0.001) SELECT "django_session"."session_key", "django_session"."session_data", "django_session"."expire_date" FROM "django_session" WHERE ("django_session"."session_key" = 'mz66yltn6yeqmst7fuv6sswequ3rajge' AND "django_session"."expire_date" > '2018-02-04 18:30:35.668161'); args=('mz66yltn6yeqmst7fuv6sswequ3rajge', '2018-02-04 18:30:35.668161')
DEBUG 2018-02-05 00:00:35,674 utils 19804 4864 (0.000) SELECT "Users"."last_login", "Users"."is_superuser", "Users"."id", "Users"."uuid", "Users"."email", "Users"."name", "Users"."password", "Users"."phone_number", "Users"."role", "Users"."last_login_at", "Users"."created_at", "Users"."updated_at" FROM "Users" WHERE "Users"."id" = 1; args=(1,)
DEBUG 2018-02-05 00:00:35,675 utils 19804 4864 (0.000) BEGIN; args=None
DEBUG 2018-02-05 00:00:35,677 utils 19804 4864 (0.000) SELECT "Locations"."id", "Locations"."lat", "Locations"."lng", "Locations"."time", "Locations"."next_location_id", "Locations"."user_id" FROM "Locations" WHERE "Locations"."id" = 17; args=(17,)
DEBUG 2018-02-05 00:00:35,687 utils 19804 4864 (0.000) SELECT "Users"."last_login", "Users"."is_superuser", "Users"."id", "Users"."uuid", "Users"."email", "Users"."name", "Users"."password", "Users"."phone_number", "Users"."role", "Users"."last_login_at", "Users"."created_at", "Users"."updated_at" FROM "Users" WHERE "Users"."id" = 2; args=(2,)
DEBUG 2018-02-05 00:00:35,688 utils 19804 4864 (0.000) SELECT (1) AS "a" FROM "Users" WHERE "Users"."id" = 2 LIMIT 1; args=(2,)
DEBUG 2018-02-05 00:00:35,691 utils 19804 4864 (0.001) UPDATE "Locations" SET "lat" = 52.2296756, "lng" = 21.0122287, "time" = '2018-02-01 10:11:10', "next_location_id" = NULL, "user_id" = 2 WHERE "Locations"."id" = 17; args=(52.2296756, 21.0122287, '2018-02-01 10:11:10', 2, 17)
DEBUG 2018-02-05 00:00:35,693 utils 19804 4864 (0.000) INSERT INTO "django_admin_log" ("action_time", "user_id", "content_type_id", "object_id", "object_repr", "action_flag", "change_message") VALUES ('2018-02-04 18:30:35.692161', 1, 7, '17', 'Location object', 2, '[{"changed": {"fields": ["lat", "lng"]}}]'); args=['2018-02-04 18:30:35.692161', 1, 7, '17', 'Location object', 2, '[{"changed": {"fields": ["lat", "lng"]}}]']
INFO 2018-02-05 00:00:35,902 basehttp 19804 4864 "POST /admin/location_tracker_app/location/17/change/ HTTP/1.1" 302 0
DEBUG 2018-02-05 00:00:35,912 utils 19804 20280 (0.001) SELECT "django_session"."session_key", "django_session"."session_data", "django_session"."expire_date" FROM "django_session" WHERE ("django_session"."session_key" = 'mz66yltn6yeqmst7fuv6sswequ3rajge' AND "django_session"."expire_date" > '2018-02-04 18:30:35.909661'); args=('mz66yltn6yeqmst7fuv6sswequ3rajge', '2018-02-04 18:30:35.909661')
DEBUG 2018-02-05 00:00:35,914 utils 19804 20280 (0.000) SELECT "Users"."last_login", "Users"."is_superuser", "Users"."id", "Users"."uuid", "Users"."email", "Users"."name", "Users"."password", "Users"."phone_number", "Users"."role", "Users"."last_login_at", "Users"."created_at", "Users"."updated_at" FROM "Users" WHERE "Users"."id" = 1; args=(1,)
DEBUG 2018-02-05 00:00:35,916 utils 19804 20280 (0.000) SELECT COUNT(*) AS "__count" FROM "Locations"; args=()
DEBUG 2018-02-05 00:00:35,917 utils 19804 20280 (0.000) SELECT COUNT(*) AS "__count" FROM "Locations"; args=()
DEBUG 2018-02-05 00:00:35,920 utils 19804 20280 (0.000) SELECT "Locations"."id", "Locations"."lat", "Locations"."lng", "Locations"."time", "Locations"."next_location_id", "Locations"."user_id" FROM "Locations" ORDER BY "Locations"."id" DESC; args=()
DEBUG 2018-02-05 00:00:35,935 base 19804 20280 Exception while resolving variable 'errors' in template 'admin/change_list.html'.
Traceback (most recent call last):
  File "C:\Users\GS-0508\AppData\Local\Programs\Python\Python36-32\lib\site-packages\django\template\base.py", line 882, in _resolve_lookup
    current = current[bit]
TypeError: 'NoneType' object is not subscriptable

During handling of the above exception, another exception occurred:

Traceback (most recent call last):
  File "C:\Users\GS-0508\AppData\Local\Programs\Python\Python36-32\lib\site-packages\django\template\base.py", line 890, in _resolve_lookup
    current = getattr(current, bit)
AttributeError: 'NoneType' object has no attribute 'errors'

During handling of the above exception, another exception occurred:

Traceback (most recent call last):
  File "C:\Users\GS-0508\AppData\Local\Programs\Python\Python36-32\lib\site-packages\django\template\base.py", line 896, in _resolve_lookup
    current = current[int(bit)]
ValueError: invalid literal for int() with base 10: 'errors'

During handling of the above exception, another exception occurred:

Traceback (most recent call last):
  File "C:\Users\GS-0508\AppData\Local\Programs\Python\Python36-32\lib\site-packages\django\template\base.py", line 903, in _resolve_lookup
    (bit, current))  # missing attribute
django.template.base.VariableDoesNotExist: Failed lookup for key [errors] in 'None'
DEBUG 2018-02-05 00:00:35,939 base 19804 20280 Exception while resolving variable 'show' in template 'admin/change_list.html'.
Traceback (most recent call last):
  File "C:\Users\GS-0508\AppData\Local\Programs\Python\Python36-32\lib\site-packages\django\template\base.py", line 882, in _resolve_lookup
    current = current[bit]
  File "C:\Users\GS-0508\AppData\Local\Programs\Python\Python36-32\lib\site-packages\django\template\context.py", line 87, in __getitem__
    raise KeyError(key)
KeyError: 'show'

During handling of the above exception, another exception occurred:

Traceback (most recent call last):
  File "C:\Users\GS-0508\AppData\Local\Programs\Python\Python36-32\lib\site-packages\django\template\base.py", line 888, in _resolve_lookup
    if isinstance(current, BaseContext) and getattr(type(current), bit):
AttributeError: type object 'RequestContext' has no attribute 'show'

During handling of the above exception, another exception occurred:

Traceback (most recent call last):
  File "C:\Users\GS-0508\AppData\Local\Programs\Python\Python36-32\lib\site-packages\django\template\base.py", line 896, in _resolve_lookup
    current = current[int(bit)]
ValueError: invalid literal for int() with base 10: 'show'

During handling of the above exception, another exception occurred:

Traceback (most recent call last):
  File "C:\Users\GS-0508\AppData\Local\Programs\Python\Python36-32\lib\site-packages\django\template\base.py", line 903, in _resolve_lookup
    (bit, current))  # missing attribute
django.template.base.VariableDoesNotExist: Failed lookup for key [show] in "[{'True': True, 'False': False, 'None': None, 'csrf_token': <SimpleLazyObject: <function csrf.<locals>._get_val at 0x04BA3E88>>}]"
DEBUG 2018-02-05 00:00:35,940 base 19804 20280 Exception while resolving variable 'is_multipart' in template 'admin/change_list.html'.
Traceback (most recent call last):
  File "C:\Users\GS-0508\AppData\Local\Programs\Python\Python36-32\lib\site-packages\django\template\base.py", line 882, in _resolve_lookup
    current = current[bit]
TypeError: 'NoneType' object is not subscriptable

During handling of the above exception, another exception occurred:

Traceback (most recent call last):
  File "C:\Users\GS-0508\AppData\Local\Programs\Python\Python36-32\lib\site-packages\django\template\base.py", line 890, in _resolve_lookup
    current = getattr(current, bit)
AttributeError: 'NoneType' object has no attribute 'is_multipart'

During handling of the above exception, another exception occurred:

Traceback (most recent call last):
  File "C:\Users\GS-0508\AppData\Local\Programs\Python\Python36-32\lib\site-packages\django\template\base.py", line 896, in _resolve_lookup
    current = current[int(bit)]
ValueError: invalid literal for int() with base 10: 'is_multipart'

During handling of the above exception, another exception occurred:

Traceback (most recent call last):
  File "C:\Users\GS-0508\AppData\Local\Programs\Python\Python36-32\lib\site-packages\django\template\base.py", line 903, in _resolve_lookup
    (bit, current))  # missing attribute
django.template.base.VariableDoesNotExist: Failed lookup for key [is_multipart] in 'None'
DEBUG 2018-02-05 00:00:35,962 base 19804 20280 Exception while resolving variable 'non_field_errors' in template 'admin/change_list.html'.
Traceback (most recent call last):
  File "C:\Users\GS-0508\AppData\Local\Programs\Python\Python36-32\lib\site-packages\django\template\base.py", line 882, in _resolve_lookup
    current = current[bit]
TypeError: 'NoneType' object is not subscriptable

During handling of the above exception, another exception occurred:

Traceback (most recent call last):
  File "C:\Users\GS-0508\AppData\Local\Programs\Python\Python36-32\lib\site-packages\django\template\base.py", line 890, in _resolve_lookup
    current = getattr(current, bit)
AttributeError: 'NoneType' object has no attribute 'non_field_errors'

During handling of the above exception, another exception occurred:

Traceback (most recent call last):
  File "C:\Users\GS-0508\AppData\Local\Programs\Python\Python36-32\lib\site-packages\django\template\base.py", line 896, in _resolve_lookup
    current = current[int(bit)]
ValueError: invalid literal for int() with base 10: 'non_field_errors'

During handling of the above exception, another exception occurred:

Traceback (most recent call last):
  File "C:\Users\GS-0508\AppData\Local\Programs\Python\Python36-32\lib\site-packages\django\template\base.py", line 903, in _resolve_lookup
    (bit, current))  # missing attribute
django.template.base.VariableDoesNotExist: Failed lookup for key [non_field_errors] in 'None'
DEBUG 2018-02-05 00:00:35,962 base 19804 20280 Exception while resolving variable 'non_field_errors' in template 'admin/change_list.html'.
Traceback (most recent call last):
  File "C:\Users\GS-0508\AppData\Local\Programs\Python\Python36-32\lib\site-packages\django\template\base.py", line 882, in _resolve_lookup
    current = current[bit]
TypeError: 'NoneType' object is not subscriptable

During handling of the above exception, another exception occurred:

Traceback (most recent call last):
  File "C:\Users\GS-0508\AppData\Local\Programs\Python\Python36-32\lib\site-packages\django\template\base.py", line 890, in _resolve_lookup
    current = getattr(current, bit)
AttributeError: 'NoneType' object has no attribute 'non_field_errors'

During handling of the above exception, another exception occurred:

Traceback (most recent call last):
  File "C:\Users\GS-0508\AppData\Local\Programs\Python\Python36-32\lib\site-packages\django\template\base.py", line 896, in _resolve_lookup
    current = current[int(bit)]
ValueError: invalid literal for int() with base 10: 'non_field_errors'

During handling of the above exception, another exception occurred:

Traceback (most recent call last):
  File "C:\Users\GS-0508\AppData\Local\Programs\Python\Python36-32\lib\site-packages\django\template\base.py", line 903, in _resolve_lookup
    (bit, current))  # missing attribute
django.template.base.VariableDoesNotExist: Failed lookup for key [non_field_errors] in 'None'
DEBUG 2018-02-05 00:00:35,963 base 19804 20280 Exception while resolving variable 'non_field_errors' in template 'admin/change_list.html'.
Traceback (most recent call last):
  File "C:\Users\GS-0508\AppData\Local\Programs\Python\Python36-32\lib\site-packages\django\template\base.py", line 882, in _resolve_lookup
    current = current[bit]
TypeError: 'NoneType' object is not subscriptable

During handling of the above exception, another exception occurred:

Traceback (most recent call last):
  File "C:\Users\GS-0508\AppData\Local\Programs\Python\Python36-32\lib\site-packages\django\template\base.py", line 890, in _resolve_lookup
    current = getattr(current, bit)
AttributeError: 'NoneType' object has no attribute 'non_field_errors'

During handling of the above exception, another exception occurred:

Traceback (most recent call last):
  File "C:\Users\GS-0508\AppData\Local\Programs\Python\Python36-32\lib\site-packages\django\template\base.py", line 896, in _resolve_lookup
    current = current[int(bit)]
ValueError: invalid literal for int() with base 10: 'non_field_errors'

During handling of the above exception, another exception occurred:

Traceback (most recent call last):
  File "C:\Users\GS-0508\AppData\Local\Programs\Python\Python36-32\lib\site-packages\django\template\base.py", line 903, in _resolve_lookup
    (bit, current))  # missing attribute
django.template.base.VariableDoesNotExist: Failed lookup for key [non_field_errors] in 'None'
INFO 2018-02-05 00:00:35,968 basehttp 19804 20280 "GET /admin/location_tracker_app/location/ HTTP/1.1" 200 4987
DEBUG 2018-02-05 00:00:36,011 utils 19804 19404 (0.004) SELECT "django_session"."session_key", "django_session"."session_data", "django_session"."expire_date" FROM "django_session" WHERE ("django_session"."session_key" = 'mz66yltn6yeqmst7fuv6sswequ3rajge' AND "django_session"."expire_date" > '2018-02-04 18:30:36.004661'); args=('mz66yltn6yeqmst7fuv6sswequ3rajge', '2018-02-04 18:30:36.004661')
DEBUG 2018-02-05 00:00:36,014 utils 19804 19404 (0.001) SELECT "Users"."last_login", "Users"."is_superuser", "Users"."id", "Users"."uuid", "Users"."email", "Users"."name", "Users"."password", "Users"."phone_number", "Users"."role", "Users"."last_login_at", "Users"."created_at", "Users"."updated_at" FROM "Users" WHERE "Users"."id" = 1; args=(1,)
INFO 2018-02-05 00:00:36,018 basehttp 19804 19404 "GET /admin/jsi18n/ HTTP/1.1" 200 3189
DEBUG 2018-02-05 00:00:38,598 utils 19804 13464 (0.003) SELECT "django_session"."session_key", "django_session"."session_data", "django_session"."expire_date" FROM "django_session" WHERE ("django_session"."session_key" = 'mz66yltn6yeqmst7fuv6sswequ3rajge' AND "django_session"."expire_date" > '2018-02-04 18:30:38.590161'); args=('mz66yltn6yeqmst7fuv6sswequ3rajge', '2018-02-04 18:30:38.590161')
DEBUG 2018-02-05 00:00:38,604 utils 19804 13464 (0.001) SELECT "Users"."last_login", "Users"."is_superuser", "Users"."id", "Users"."uuid", "Users"."email", "Users"."name", "Users"."password", "Users"."phone_number", "Users"."role", "Users"."last_login_at", "Users"."created_at", "Users"."updated_at" FROM "Users" WHERE "Users"."id" = 1; args=(1,)
DEBUG 2018-02-05 00:00:38,606 utils 19804 13464 (0.000) BEGIN; args=None
DEBUG 2018-02-05 00:00:38,609 utils 19804 13464 (0.001) SELECT "Locations"."id", "Locations"."lat", "Locations"."lng", "Locations"."time", "Locations"."next_location_id", "Locations"."user_id" FROM "Locations" WHERE "Locations"."id" = 16; args=(16,)
DEBUG 2018-02-05 00:00:38,706 utils 19804 13464 (0.000) SELECT "Locations"."id", "Locations"."lat", "Locations"."lng", "Locations"."time", "Locations"."next_location_id", "Locations"."user_id" FROM "Locations"; args=()
DEBUG 2018-02-05 00:00:38,721 base 19804 13464 Exception while resolving variable 'can_delete_related' in template 'admin/widgets/related_widget_wrapper.html'.
Traceback (most recent call last):
  File "C:\Users\GS-0508\AppData\Local\Programs\Python\Python36-32\lib\site-packages\django\template\base.py", line 882, in _resolve_lookup
    current = current[bit]
  File "C:\Users\GS-0508\AppData\Local\Programs\Python\Python36-32\lib\site-packages\django\template\context.py", line 87, in __getitem__
    raise KeyError(key)
KeyError: 'can_delete_related'

During handling of the above exception, another exception occurred:

Traceback (most recent call last):
  File "C:\Users\GS-0508\AppData\Local\Programs\Python\Python36-32\lib\site-packages\django\template\base.py", line 888, in _resolve_lookup
    if isinstance(current, BaseContext) and getattr(type(current), bit):
AttributeError: type object 'Context' has no attribute 'can_delete_related'

During handling of the above exception, another exception occurred:

Traceback (most recent call last):
  File "C:\Users\GS-0508\AppData\Local\Programs\Python\Python36-32\lib\site-packages\django\template\base.py", line 896, in _resolve_lookup
    current = current[int(bit)]
ValueError: invalid literal for int() with base 10: 'can_delete_related'

During handling of the above exception, another exception occurred:

Traceback (most recent call last):
  File "C:\Users\GS-0508\AppData\Local\Programs\Python\Python36-32\lib\site-packages\django\template\base.py", line 903, in _resolve_lookup
    (bit, current))  # missing attribute
django.template.base.VariableDoesNotExist: Failed lookup for key [can_delete_related] in '[{\'True\': True, \'False\': False, \'None\': None}, {\'rendered_widget\': \'<select name="next_location" id="id_next_location">\\n  <option value="">---------</option>\\n\\n  <option value="15">Location object</option>\\n\\n  <option value="16">Location object</option>\\n\\n  <option value="17" selected>Location object</option>\\n\\n</select>\', \'name\': \'next_location\', \'url_params\': \'_to_field=id&_popup=1\', \'model\': \'location\', \'can_change_related\': True, \'change_related_template_url\': \'/admin/location_tracker_app/location/__fk__/change/\', \'can_add_related\': True, \'add_related_url\': \'/admin/location_tracker_app/location/add/\'}, {\'block\': <Block Node: links. Contents: [<TextNode: \'\\n        \'>, <django.template.defaulttags.SpacelessNode object at 0x04A82910>, <TextNode: \'\\n    \'>]>}]'
DEBUG 2018-02-05 00:00:38,727 utils 19804 13464 (0.000) SELECT "Users"."last_login", "Users"."is_superuser", "Users"."id", "Users"."uuid", "Users"."email", "Users"."name", "Users"."password", "Users"."phone_number", "Users"."role", "Users"."last_login_at", "Users"."created_at", "Users"."updated_at" FROM "Users"; args=()
DEBUG 2018-02-05 00:00:38,739 base 19804 13464 Exception while resolving variable 'can_delete_related' in template 'admin/widgets/related_widget_wrapper.html'.
Traceback (most recent call last):
  File "C:\Users\GS-0508\AppData\Local\Programs\Python\Python36-32\lib\site-packages\django\template\base.py", line 882, in _resolve_lookup
    current = current[bit]
  File "C:\Users\GS-0508\AppData\Local\Programs\Python\Python36-32\lib\site-packages\django\template\context.py", line 87, in __getitem__
    raise KeyError(key)
KeyError: 'can_delete_related'

During handling of the above exception, another exception occurred:

Traceback (most recent call last):
  File "C:\Users\GS-0508\AppData\Local\Programs\Python\Python36-32\lib\site-packages\django\template\base.py", line 888, in _resolve_lookup
    if isinstance(current, BaseContext) and getattr(type(current), bit):
AttributeError: type object 'Context' has no attribute 'can_delete_related'

During handling of the above exception, another exception occurred:

Traceback (most recent call last):
  File "C:\Users\GS-0508\AppData\Local\Programs\Python\Python36-32\lib\site-packages\django\template\base.py", line 896, in _resolve_lookup
    current = current[int(bit)]
ValueError: invalid literal for int() with base 10: 'can_delete_related'

During handling of the above exception, another exception occurred:

Traceback (most recent call last):
  File "C:\Users\GS-0508\AppData\Local\Programs\Python\Python36-32\lib\site-packages\django\template\base.py", line 903, in _resolve_lookup
    (bit, current))  # missing attribute
django.template.base.VariableDoesNotExist: Failed lookup for key [can_delete_related] in '[{\'True\': True, \'False\': False, \'None\': None}, {\'rendered_widget\': \'<select name="user" required id="id_user">\\n  <option value="">---------</option>\\n\\n  <option value="1">admin@lct.com</option>\\n\\n  <option value="2" selected>user1@gmail.com</option>\\n\\n</select>\', \'name\': \'user\', \'url_params\': \'_to_field=id&_popup=1\', \'model\': \'user\', \'can_change_related\': True, \'change_related_template_url\': \'/admin/location_tracker_app/user/__fk__/change/\', \'can_add_related\': True, \'add_related_url\': \'/admin/location_tracker_app/user/add/\'}, {\'block\': <Block Node: links. Contents: [<TextNode: \'\\n        \'>, <django.template.defaulttags.SpacelessNode object at 0x04A82B50>, <TextNode: \'\\n    \'>]>}]'
INFO 2018-02-05 00:00:38,749 basehttp 19804 13464 "GET /admin/location_tracker_app/location/16/change/ HTTP/1.1" 200 8055
DEBUG 2018-02-05 00:00:38,811 utils 19804 13508 (0.002) SELECT "django_session"."session_key", "django_session"."session_data", "django_session"."expire_date" FROM "django_session" WHERE ("django_session"."session_key" = 'mz66yltn6yeqmst7fuv6sswequ3rajge' AND "django_session"."expire_date" > '2018-02-04 18:30:38.805661'); args=('mz66yltn6yeqmst7fuv6sswequ3rajge', '2018-02-04 18:30:38.805661')
DEBUG 2018-02-05 00:00:38,815 utils 19804 13508 (0.001) SELECT "Users"."last_login", "Users"."is_superuser", "Users"."id", "Users"."uuid", "Users"."email", "Users"."name", "Users"."password", "Users"."phone_number", "Users"."role", "Users"."last_login_at", "Users"."created_at", "Users"."updated_at" FROM "Users" WHERE "Users"."id" = 1; args=(1,)
INFO 2018-02-05 00:00:38,822 basehttp 19804 13508 "GET /admin/jsi18n/ HTTP/1.1" 200 3189
DEBUG 2018-02-05 00:00:58,953 utils 19804 10676 (0.003) SELECT "django_session"."session_key", "django_session"."session_data", "django_session"."expire_date" FROM "django_session" WHERE ("django_session"."session_key" = 'mz66yltn6yeqmst7fuv6sswequ3rajge' AND "django_session"."expire_date" > '2018-02-04 18:30:58.944161'); args=('mz66yltn6yeqmst7fuv6sswequ3rajge', '2018-02-04 18:30:58.944161')
DEBUG 2018-02-05 00:00:58,956 utils 19804 10676 (0.001) SELECT "Users"."last_login", "Users"."is_superuser", "Users"."id", "Users"."uuid", "Users"."email", "Users"."name", "Users"."password", "Users"."phone_number", "Users"."role", "Users"."last_login_at", "Users"."created_at", "Users"."updated_at" FROM "Users" WHERE "Users"."id" = 1; args=(1,)
DEBUG 2018-02-05 00:00:58,957 utils 19804 10676 (0.000) BEGIN; args=None
DEBUG 2018-02-05 00:00:58,959 utils 19804 10676 (0.000) SELECT "Locations"."id", "Locations"."lat", "Locations"."lng", "Locations"."time", "Locations"."next_location_id", "Locations"."user_id" FROM "Locations" WHERE "Locations"."id" = 16; args=(16,)
DEBUG 2018-02-05 00:00:58,965 utils 19804 10676 (0.000) SELECT "Locations"."id", "Locations"."lat", "Locations"."lng", "Locations"."time", "Locations"."next_location_id", "Locations"."user_id" FROM "Locations" WHERE "Locations"."id" = 17; args=(17,)
DEBUG 2018-02-05 00:00:58,967 utils 19804 10676 (0.000) SELECT "Users"."last_login", "Users"."is_superuser", "Users"."id", "Users"."uuid", "Users"."email", "Users"."name", "Users"."password", "Users"."phone_number", "Users"."role", "Users"."last_login_at", "Users"."created_at", "Users"."updated_at" FROM "Users" WHERE "Users"."id" = 2; args=(2,)
DEBUG 2018-02-05 00:00:58,969 utils 19804 10676 (0.000) SELECT (1) AS "a" FROM "Locations" WHERE "Locations"."id" = 17 LIMIT 1; args=(17,)
DEBUG 2018-02-05 00:00:58,970 utils 19804 10676 (0.000) SELECT (1) AS "a" FROM "Users" WHERE "Users"."id" = 2 LIMIT 1; args=(2,)
DEBUG 2018-02-05 00:00:58,974 utils 19804 10676 (0.002) UPDATE "Locations" SET "lat" = 52.406374, "lng" = 16.9251681, "time" = '2018-02-01 10:11:10', "next_location_id" = 17, "user_id" = 2 WHERE "Locations"."id" = 16; args=(52.406374, 16.9251681, '2018-02-01 10:11:10', 17, 2, 16)
DEBUG 2018-02-05 00:00:58,976 utils 19804 10676 (0.000) INSERT INTO "django_admin_log" ("action_time", "user_id", "content_type_id", "object_id", "object_repr", "action_flag", "change_message") VALUES ('2018-02-04 18:30:58.975161', 1, 7, '16', 'Location object', 2, '[{"changed": {"fields": ["lat", "lng"]}}]'); args=['2018-02-04 18:30:58.975161', 1, 7, '16', 'Location object', 2, '[{"changed": {"fields": ["lat", "lng"]}}]']
INFO 2018-02-05 00:00:59,304 basehttp 19804 10676 "POST /admin/location_tracker_app/location/16/change/ HTTP/1.1" 302 0
DEBUG 2018-02-05 00:00:59,325 utils 19804 16636 (0.002) SELECT "django_session"."session_key", "django_session"."session_data", "django_session"."expire_date" FROM "django_session" WHERE ("django_session"."session_key" = 'mz66yltn6yeqmst7fuv6sswequ3rajge' AND "django_session"."expire_date" > '2018-02-04 18:30:59.317661'); args=('mz66yltn6yeqmst7fuv6sswequ3rajge', '2018-02-04 18:30:59.317661')
DEBUG 2018-02-05 00:00:59,328 utils 19804 16636 (0.001) SELECT "Users"."last_login", "Users"."is_superuser", "Users"."id", "Users"."uuid", "Users"."email", "Users"."name", "Users"."password", "Users"."phone_number", "Users"."role", "Users"."last_login_at", "Users"."created_at", "Users"."updated_at" FROM "Users" WHERE "Users"."id" = 1; args=(1,)
DEBUG 2018-02-05 00:00:59,332 utils 19804 16636 (0.001) SELECT COUNT(*) AS "__count" FROM "Locations"; args=()
DEBUG 2018-02-05 00:00:59,334 utils 19804 16636 (0.000) SELECT COUNT(*) AS "__count" FROM "Locations"; args=()
DEBUG 2018-02-05 00:00:59,339 utils 19804 16636 (0.000) SELECT "Locations"."id", "Locations"."lat", "Locations"."lng", "Locations"."time", "Locations"."next_location_id", "Locations"."user_id" FROM "Locations" ORDER BY "Locations"."id" DESC; args=()
DEBUG 2018-02-05 00:00:59,370 base 19804 16636 Exception while resolving variable 'errors' in template 'admin/change_list.html'.
Traceback (most recent call last):
  File "C:\Users\GS-0508\AppData\Local\Programs\Python\Python36-32\lib\site-packages\django\template\base.py", line 882, in _resolve_lookup
    current = current[bit]
TypeError: 'NoneType' object is not subscriptable

During handling of the above exception, another exception occurred:

Traceback (most recent call last):
  File "C:\Users\GS-0508\AppData\Local\Programs\Python\Python36-32\lib\site-packages\django\template\base.py", line 890, in _resolve_lookup
    current = getattr(current, bit)
AttributeError: 'NoneType' object has no attribute 'errors'

During handling of the above exception, another exception occurred:

Traceback (most recent call last):
  File "C:\Users\GS-0508\AppData\Local\Programs\Python\Python36-32\lib\site-packages\django\template\base.py", line 896, in _resolve_lookup
    current = current[int(bit)]
ValueError: invalid literal for int() with base 10: 'errors'

During handling of the above exception, another exception occurred:

Traceback (most recent call last):
  File "C:\Users\GS-0508\AppData\Local\Programs\Python\Python36-32\lib\site-packages\django\template\base.py", line 903, in _resolve_lookup
    (bit, current))  # missing attribute
django.template.base.VariableDoesNotExist: Failed lookup for key [errors] in 'None'
DEBUG 2018-02-05 00:00:59,376 base 19804 16636 Exception while resolving variable 'show' in template 'admin/change_list.html'.
Traceback (most recent call last):
  File "C:\Users\GS-0508\AppData\Local\Programs\Python\Python36-32\lib\site-packages\django\template\base.py", line 882, in _resolve_lookup
    current = current[bit]
  File "C:\Users\GS-0508\AppData\Local\Programs\Python\Python36-32\lib\site-packages\django\template\context.py", line 87, in __getitem__
    raise KeyError(key)
KeyError: 'show'

During handling of the above exception, another exception occurred:

Traceback (most recent call last):
  File "C:\Users\GS-0508\AppData\Local\Programs\Python\Python36-32\lib\site-packages\django\template\base.py", line 888, in _resolve_lookup
    if isinstance(current, BaseContext) and getattr(type(current), bit):
AttributeError: type object 'RequestContext' has no attribute 'show'

During handling of the above exception, another exception occurred:

Traceback (most recent call last):
  File "C:\Users\GS-0508\AppData\Local\Programs\Python\Python36-32\lib\site-packages\django\template\base.py", line 896, in _resolve_lookup
    current = current[int(bit)]
ValueError: invalid literal for int() with base 10: 'show'

During handling of the above exception, another exception occurred:

Traceback (most recent call last):
  File "C:\Users\GS-0508\AppData\Local\Programs\Python\Python36-32\lib\site-packages\django\template\base.py", line 903, in _resolve_lookup
    (bit, current))  # missing attribute
django.template.base.VariableDoesNotExist: Failed lookup for key [show] in "[{'True': True, 'False': False, 'None': None, 'csrf_token': <SimpleLazyObject: <function csrf.<locals>._get_val at 0x04BEC150>>}]"
DEBUG 2018-02-05 00:00:59,377 base 19804 16636 Exception while resolving variable 'is_multipart' in template 'admin/change_list.html'.
Traceback (most recent call last):
  File "C:\Users\GS-0508\AppData\Local\Programs\Python\Python36-32\lib\site-packages\django\template\base.py", line 882, in _resolve_lookup
    current = current[bit]
TypeError: 'NoneType' object is not subscriptable

During handling of the above exception, another exception occurred:

Traceback (most recent call last):
  File "C:\Users\GS-0508\AppData\Local\Programs\Python\Python36-32\lib\site-packages\django\template\base.py", line 890, in _resolve_lookup
    current = getattr(current, bit)
AttributeError: 'NoneType' object has no attribute 'is_multipart'

During handling of the above exception, another exception occurred:

Traceback (most recent call last):
  File "C:\Users\GS-0508\AppData\Local\Programs\Python\Python36-32\lib\site-packages\django\template\base.py", line 896, in _resolve_lookup
    current = current[int(bit)]
ValueError: invalid literal for int() with base 10: 'is_multipart'

During handling of the above exception, another exception occurred:

Traceback (most recent call last):
  File "C:\Users\GS-0508\AppData\Local\Programs\Python\Python36-32\lib\site-packages\django\template\base.py", line 903, in _resolve_lookup
    (bit, current))  # missing attribute
django.template.base.VariableDoesNotExist: Failed lookup for key [is_multipart] in 'None'
DEBUG 2018-02-05 00:00:59,419 base 19804 16636 Exception while resolving variable 'non_field_errors' in template 'admin/change_list.html'.
Traceback (most recent call last):
  File "C:\Users\GS-0508\AppData\Local\Programs\Python\Python36-32\lib\site-packages\django\template\base.py", line 882, in _resolve_lookup
    current = current[bit]
TypeError: 'NoneType' object is not subscriptable

During handling of the above exception, another exception occurred:

Traceback (most recent call last):
  File "C:\Users\GS-0508\AppData\Local\Programs\Python\Python36-32\lib\site-packages\django\template\base.py", line 890, in _resolve_lookup
    current = getattr(current, bit)
AttributeError: 'NoneType' object has no attribute 'non_field_errors'

During handling of the above exception, another exception occurred:

Traceback (most recent call last):
  File "C:\Users\GS-0508\AppData\Local\Programs\Python\Python36-32\lib\site-packages\django\template\base.py", line 896, in _resolve_lookup
    current = current[int(bit)]
ValueError: invalid literal for int() with base 10: 'non_field_errors'

During handling of the above exception, another exception occurred:

Traceback (most recent call last):
  File "C:\Users\GS-0508\AppData\Local\Programs\Python\Python36-32\lib\site-packages\django\template\base.py", line 903, in _resolve_lookup
    (bit, current))  # missing attribute
django.template.base.VariableDoesNotExist: Failed lookup for key [non_field_errors] in 'None'
DEBUG 2018-02-05 00:00:59,421 base 19804 16636 Exception while resolving variable 'non_field_errors' in template 'admin/change_list.html'.
Traceback (most recent call last):
  File "C:\Users\GS-0508\AppData\Local\Programs\Python\Python36-32\lib\site-packages\django\template\base.py", line 882, in _resolve_lookup
    current = current[bit]
TypeError: 'NoneType' object is not subscriptable

During handling of the above exception, another exception occurred:

Traceback (most recent call last):
  File "C:\Users\GS-0508\AppData\Local\Programs\Python\Python36-32\lib\site-packages\django\template\base.py", line 890, in _resolve_lookup
    current = getattr(current, bit)
AttributeError: 'NoneType' object has no attribute 'non_field_errors'

During handling of the above exception, another exception occurred:

Traceback (most recent call last):
  File "C:\Users\GS-0508\AppData\Local\Programs\Python\Python36-32\lib\site-packages\django\template\base.py", line 896, in _resolve_lookup
    current = current[int(bit)]
ValueError: invalid literal for int() with base 10: 'non_field_errors'

During handling of the above exception, another exception occurred:

Traceback (most recent call last):
  File "C:\Users\GS-0508\AppData\Local\Programs\Python\Python36-32\lib\site-packages\django\template\base.py", line 903, in _resolve_lookup
    (bit, current))  # missing attribute
django.template.base.VariableDoesNotExist: Failed lookup for key [non_field_errors] in 'None'
DEBUG 2018-02-05 00:00:59,422 base 19804 16636 Exception while resolving variable 'non_field_errors' in template 'admin/change_list.html'.
Traceback (most recent call last):
  File "C:\Users\GS-0508\AppData\Local\Programs\Python\Python36-32\lib\site-packages\django\template\base.py", line 882, in _resolve_lookup
    current = current[bit]
TypeError: 'NoneType' object is not subscriptable

During handling of the above exception, another exception occurred:

Traceback (most recent call last):
  File "C:\Users\GS-0508\AppData\Local\Programs\Python\Python36-32\lib\site-packages\django\template\base.py", line 890, in _resolve_lookup
    current = getattr(current, bit)
AttributeError: 'NoneType' object has no attribute 'non_field_errors'

During handling of the above exception, another exception occurred:

Traceback (most recent call last):
  File "C:\Users\GS-0508\AppData\Local\Programs\Python\Python36-32\lib\site-packages\django\template\base.py", line 896, in _resolve_lookup
    current = current[int(bit)]
ValueError: invalid literal for int() with base 10: 'non_field_errors'

During handling of the above exception, another exception occurred:

Traceback (most recent call last):
  File "C:\Users\GS-0508\AppData\Local\Programs\Python\Python36-32\lib\site-packages\django\template\base.py", line 903, in _resolve_lookup
    (bit, current))  # missing attribute
django.template.base.VariableDoesNotExist: Failed lookup for key [non_field_errors] in 'None'
INFO 2018-02-05 00:00:59,431 basehttp 19804 16636 "GET /admin/location_tracker_app/location/ HTTP/1.1" 200 4987
DEBUG 2018-02-05 00:00:59,492 utils 19804 15028 (0.002) SELECT "django_session"."session_key", "django_session"."session_data", "django_session"."expire_date" FROM "django_session" WHERE ("django_session"."session_key" = 'mz66yltn6yeqmst7fuv6sswequ3rajge' AND "django_session"."expire_date" > '2018-02-04 18:30:59.485661'); args=('mz66yltn6yeqmst7fuv6sswequ3rajge', '2018-02-04 18:30:59.485661')
DEBUG 2018-02-05 00:00:59,495 utils 19804 15028 (0.000) SELECT "Users"."last_login", "Users"."is_superuser", "Users"."id", "Users"."uuid", "Users"."email", "Users"."name", "Users"."password", "Users"."phone_number", "Users"."role", "Users"."last_login_at", "Users"."created_at", "Users"."updated_at" FROM "Users" WHERE "Users"."id" = 1; args=(1,)
INFO 2018-02-05 00:00:59,499 basehttp 19804 15028 "GET /admin/jsi18n/ HTTP/1.1" 200 3189
DEBUG 2018-02-05 00:01:00,621 utils 19804 14224 (0.002) SELECT "django_session"."session_key", "django_session"."session_data", "django_session"."expire_date" FROM "django_session" WHERE ("django_session"."session_key" = 'mz66yltn6yeqmst7fuv6sswequ3rajge' AND "django_session"."expire_date" > '2018-02-04 18:31:00.615661'); args=('mz66yltn6yeqmst7fuv6sswequ3rajge', '2018-02-04 18:31:00.615661')
DEBUG 2018-02-05 00:01:00,625 utils 19804 14224 (0.001) SELECT "Users"."last_login", "Users"."is_superuser", "Users"."id", "Users"."uuid", "Users"."email", "Users"."name", "Users"."password", "Users"."phone_number", "Users"."role", "Users"."last_login_at", "Users"."created_at", "Users"."updated_at" FROM "Users" WHERE "Users"."id" = 1; args=(1,)
DEBUG 2018-02-05 00:01:00,627 utils 19804 14224 (0.000) BEGIN; args=None
DEBUG 2018-02-05 00:01:00,631 utils 19804 14224 (0.001) SELECT "Locations"."id", "Locations"."lat", "Locations"."lng", "Locations"."time", "Locations"."next_location_id", "Locations"."user_id" FROM "Locations" WHERE "Locations"."id" = 15; args=(15,)
DEBUG 2018-02-05 00:01:00,703 utils 19804 14224 (0.000) SELECT "Locations"."id", "Locations"."lat", "Locations"."lng", "Locations"."time", "Locations"."next_location_id", "Locations"."user_id" FROM "Locations"; args=()
DEBUG 2018-02-05 00:01:00,712 base 19804 14224 Exception while resolving variable 'can_delete_related' in template 'admin/widgets/related_widget_wrapper.html'.
Traceback (most recent call last):
  File "C:\Users\GS-0508\AppData\Local\Programs\Python\Python36-32\lib\site-packages\django\template\base.py", line 882, in _resolve_lookup
    current = current[bit]
  File "C:\Users\GS-0508\AppData\Local\Programs\Python\Python36-32\lib\site-packages\django\template\context.py", line 87, in __getitem__
    raise KeyError(key)
KeyError: 'can_delete_related'

During handling of the above exception, another exception occurred:

Traceback (most recent call last):
  File "C:\Users\GS-0508\AppData\Local\Programs\Python\Python36-32\lib\site-packages\django\template\base.py", line 888, in _resolve_lookup
    if isinstance(current, BaseContext) and getattr(type(current), bit):
AttributeError: type object 'Context' has no attribute 'can_delete_related'

During handling of the above exception, another exception occurred:

Traceback (most recent call last):
  File "C:\Users\GS-0508\AppData\Local\Programs\Python\Python36-32\lib\site-packages\django\template\base.py", line 896, in _resolve_lookup
    current = current[int(bit)]
ValueError: invalid literal for int() with base 10: 'can_delete_related'

During handling of the above exception, another exception occurred:

Traceback (most recent call last):
  File "C:\Users\GS-0508\AppData\Local\Programs\Python\Python36-32\lib\site-packages\django\template\base.py", line 903, in _resolve_lookup
    (bit, current))  # missing attribute
django.template.base.VariableDoesNotExist: Failed lookup for key [can_delete_related] in '[{\'True\': True, \'False\': False, \'None\': None}, {\'rendered_widget\': \'<select name="next_location" id="id_next_location">\\n  <option value="">---------</option>\\n\\n  <option value="15">Location object</option>\\n\\n  <option value="16" selected>Location object</option>\\n\\n  <option value="17">Location object</option>\\n\\n</select>\', \'name\': \'next_location\', \'url_params\': \'_to_field=id&_popup=1\', \'model\': \'location\', \'can_change_related\': True, \'change_related_template_url\': \'/admin/location_tracker_app/location/__fk__/change/\', \'can_add_related\': True, \'add_related_url\': \'/admin/location_tracker_app/location/add/\'}, {\'block\': <Block Node: links. Contents: [<TextNode: \'\\n        \'>, <django.template.defaulttags.SpacelessNode object at 0x04A95A90>, <TextNode: \'\\n    \'>]>}]'
DEBUG 2018-02-05 00:01:00,716 utils 19804 14224 (0.000) SELECT "Users"."last_login", "Users"."is_superuser", "Users"."id", "Users"."uuid", "Users"."email", "Users"."name", "Users"."password", "Users"."phone_number", "Users"."role", "Users"."last_login_at", "Users"."created_at", "Users"."updated_at" FROM "Users"; args=()
DEBUG 2018-02-05 00:01:00,727 base 19804 14224 Exception while resolving variable 'can_delete_related' in template 'admin/widgets/related_widget_wrapper.html'.
Traceback (most recent call last):
  File "C:\Users\GS-0508\AppData\Local\Programs\Python\Python36-32\lib\site-packages\django\template\base.py", line 882, in _resolve_lookup
    current = current[bit]
  File "C:\Users\GS-0508\AppData\Local\Programs\Python\Python36-32\lib\site-packages\django\template\context.py", line 87, in __getitem__
    raise KeyError(key)
KeyError: 'can_delete_related'

During handling of the above exception, another exception occurred:

Traceback (most recent call last):
  File "C:\Users\GS-0508\AppData\Local\Programs\Python\Python36-32\lib\site-packages\django\template\base.py", line 888, in _resolve_lookup
    if isinstance(current, BaseContext) and getattr(type(current), bit):
AttributeError: type object 'Context' has no attribute 'can_delete_related'

During handling of the above exception, another exception occurred:

Traceback (most recent call last):
  File "C:\Users\GS-0508\AppData\Local\Programs\Python\Python36-32\lib\site-packages\django\template\base.py", line 896, in _resolve_lookup
    current = current[int(bit)]
ValueError: invalid literal for int() with base 10: 'can_delete_related'

During handling of the above exception, another exception occurred:

Traceback (most recent call last):
  File "C:\Users\GS-0508\AppData\Local\Programs\Python\Python36-32\lib\site-packages\django\template\base.py", line 903, in _resolve_lookup
    (bit, current))  # missing attribute
django.template.base.VariableDoesNotExist: Failed lookup for key [can_delete_related] in '[{\'True\': True, \'False\': False, \'None\': None}, {\'rendered_widget\': \'<select name="user" required id="id_user">\\n  <option value="">---------</option>\\n\\n  <option value="1">admin@lct.com</option>\\n\\n  <option value="2" selected>user1@gmail.com</option>\\n\\n</select>\', \'name\': \'user\', \'url_params\': \'_to_field=id&_popup=1\', \'model\': \'user\', \'can_change_related\': True, \'change_related_template_url\': \'/admin/location_tracker_app/user/__fk__/change/\', \'can_add_related\': True, \'add_related_url\': \'/admin/location_tracker_app/user/add/\'}, {\'block\': <Block Node: links. Contents: [<TextNode: \'\\n        \'>, <django.template.defaulttags.SpacelessNode object at 0x04C0F910>, <TextNode: \'\\n    \'>]>}]'
INFO 2018-02-05 00:01:00,734 basehttp 19804 14224 "GET /admin/location_tracker_app/location/15/change/ HTTP/1.1" 200 8055
DEBUG 2018-02-05 00:01:00,766 utils 19804 2780 (0.001) SELECT "django_session"."session_key", "django_session"."session_data", "django_session"."expire_date" FROM "django_session" WHERE ("django_session"."session_key" = 'mz66yltn6yeqmst7fuv6sswequ3rajge' AND "django_session"."expire_date" > '2018-02-04 18:31:00.762161'); args=('mz66yltn6yeqmst7fuv6sswequ3rajge', '2018-02-04 18:31:00.762161')
DEBUG 2018-02-05 00:01:00,768 utils 19804 2780 (0.001) SELECT "Users"."last_login", "Users"."is_superuser", "Users"."id", "Users"."uuid", "Users"."email", "Users"."name", "Users"."password", "Users"."phone_number", "Users"."role", "Users"."last_login_at", "Users"."created_at", "Users"."updated_at" FROM "Users" WHERE "Users"."id" = 1; args=(1,)
INFO 2018-02-05 00:01:00,772 basehttp 19804 2780 "GET /admin/jsi18n/ HTTP/1.1" 200 3189
DEBUG 2018-02-05 00:01:02,602 utils 19804 16816 (0.001) SELECT "django_session"."session_key", "django_session"."session_data", "django_session"."expire_date" FROM "django_session" WHERE ("django_session"."session_key" = 'mz66yltn6yeqmst7fuv6sswequ3rajge' AND "django_session"."expire_date" > '2018-02-04 18:31:02.597661'); args=('mz66yltn6yeqmst7fuv6sswequ3rajge', '2018-02-04 18:31:02.597661')
DEBUG 2018-02-05 00:01:02,605 utils 19804 16816 (0.001) SELECT "Users"."last_login", "Users"."is_superuser", "Users"."id", "Users"."uuid", "Users"."email", "Users"."name", "Users"."password", "Users"."phone_number", "Users"."role", "Users"."last_login_at", "Users"."created_at", "Users"."updated_at" FROM "Users" WHERE "Users"."id" = 1; args=(1,)
DEBUG 2018-02-05 00:01:02,607 utils 19804 16816 (0.000) BEGIN; args=None
DEBUG 2018-02-05 00:01:02,610 utils 19804 16816 (0.000) SELECT "Locations"."id", "Locations"."lat", "Locations"."lng", "Locations"."time", "Locations"."next_location_id", "Locations"."user_id" FROM "Locations" WHERE "Locations"."id" = 15; args=(15,)
DEBUG 2018-02-05 00:01:02,614 utils 19804 16816 (0.000) SELECT "Locations"."id", "Locations"."lat", "Locations"."lng", "Locations"."time", "Locations"."next_location_id", "Locations"."user_id", T2."id", T2."lat", T2."lng", T2."time", T2."next_location_id", T2."user_id" FROM "Locations" INNER JOIN "Locations" T2 ON ("Locations"."next_location_id" = T2."id") WHERE "Locations"."next_location_id" IN (15); args=(15,)
INFO 2018-02-05 00:01:02,721 basehttp 19804 16816 "GET /admin/location_tracker_app/location/15/delete/ HTTP/1.1" 200 3135
DEBUG 2018-02-05 00:01:04,338 utils 19804 8528 (0.001) SELECT "django_session"."session_key", "django_session"."session_data", "django_session"."expire_date" FROM "django_session" WHERE ("django_session"."session_key" = 'mz66yltn6yeqmst7fuv6sswequ3rajge' AND "django_session"."expire_date" > '2018-02-04 18:31:04.334161'); args=('mz66yltn6yeqmst7fuv6sswequ3rajge', '2018-02-04 18:31:04.334161')
DEBUG 2018-02-05 00:01:04,340 utils 19804 8528 (0.000) SELECT "Users"."last_login", "Users"."is_superuser", "Users"."id", "Users"."uuid", "Users"."email", "Users"."name", "Users"."password", "Users"."phone_number", "Users"."role", "Users"."last_login_at", "Users"."created_at", "Users"."updated_at" FROM "Users" WHERE "Users"."id" = 1; args=(1,)
DEBUG 2018-02-05 00:01:04,341 utils 19804 8528 (0.000) BEGIN; args=None
DEBUG 2018-02-05 00:01:04,342 utils 19804 8528 (0.000) SELECT "Locations"."id", "Locations"."lat", "Locations"."lng", "Locations"."time", "Locations"."next_location_id", "Locations"."user_id" FROM "Locations" WHERE "Locations"."id" = 15; args=(15,)
DEBUG 2018-02-05 00:01:04,345 utils 19804 8528 (0.000) SELECT "Locations"."id", "Locations"."lat", "Locations"."lng", "Locations"."time", "Locations"."next_location_id", "Locations"."user_id", T2."id", T2."lat", T2."lng", T2."time", T2."next_location_id", T2."user_id" FROM "Locations" INNER JOIN "Locations" T2 ON ("Locations"."next_location_id" = T2."id") WHERE "Locations"."next_location_id" IN (15); args=(15,)
DEBUG 2018-02-05 00:01:04,349 utils 19804 8528 (0.003) INSERT INTO "django_admin_log" ("action_time", "user_id", "content_type_id", "object_id", "object_repr", "action_flag", "change_message") VALUES ('2018-02-04 18:31:04.346661', 1, 7, '15', 'Location object', 3, ''); args=['2018-02-04 18:31:04.346661', 1, 7, '15', 'Location object', 3, '']
DEBUG 2018-02-05 00:01:04,351 utils 19804 8528 (0.000) SELECT "Locations"."id", "Locations"."lat", "Locations"."lng", "Locations"."time", "Locations"."next_location_id", "Locations"."user_id" FROM "Locations" WHERE "Locations"."next_location_id" IN (15); args=(15,)
DEBUG 2018-02-05 00:01:04,352 utils 19804 8528 (0.001) DELETE FROM "Locations" WHERE "Locations"."id" IN (15); args=(15,)
INFO 2018-02-05 00:01:04,686 basehttp 19804 8528 "POST /admin/location_tracker_app/location/15/delete/ HTTP/1.1" 302 0
DEBUG 2018-02-05 00:01:04,706 utils 19804 20216 (0.001) SELECT "django_session"."session_key", "django_session"."session_data", "django_session"."expire_date" FROM "django_session" WHERE ("django_session"."session_key" = 'mz66yltn6yeqmst7fuv6sswequ3rajge' AND "django_session"."expire_date" > '2018-02-04 18:31:04.699161'); args=('mz66yltn6yeqmst7fuv6sswequ3rajge', '2018-02-04 18:31:04.699161')
DEBUG 2018-02-05 00:01:04,708 utils 19804 20216 (0.001) SELECT "Users"."last_login", "Users"."is_superuser", "Users"."id", "Users"."uuid", "Users"."email", "Users"."name", "Users"."password", "Users"."phone_number", "Users"."role", "Users"."last_login_at", "Users"."created_at", "Users"."updated_at" FROM "Users" WHERE "Users"."id" = 1; args=(1,)
DEBUG 2018-02-05 00:01:04,712 utils 19804 20216 (0.000) SELECT COUNT(*) AS "__count" FROM "Locations"; args=()
DEBUG 2018-02-05 00:01:04,714 utils 19804 20216 (0.000) SELECT COUNT(*) AS "__count" FROM "Locations"; args=()
DEBUG 2018-02-05 00:01:04,718 utils 19804 20216 (0.000) SELECT "Locations"."id", "Locations"."lat", "Locations"."lng", "Locations"."time", "Locations"."next_location_id", "Locations"."user_id" FROM "Locations" ORDER BY "Locations"."id" DESC; args=()
DEBUG 2018-02-05 00:01:04,741 base 19804 20216 Exception while resolving variable 'errors' in template 'admin/change_list.html'.
Traceback (most recent call last):
  File "C:\Users\GS-0508\AppData\Local\Programs\Python\Python36-32\lib\site-packages\django\template\base.py", line 882, in _resolve_lookup
    current = current[bit]
TypeError: 'NoneType' object is not subscriptable

During handling of the above exception, another exception occurred:

Traceback (most recent call last):
  File "C:\Users\GS-0508\AppData\Local\Programs\Python\Python36-32\lib\site-packages\django\template\base.py", line 890, in _resolve_lookup
    current = getattr(current, bit)
AttributeError: 'NoneType' object has no attribute 'errors'

During handling of the above exception, another exception occurred:

Traceback (most recent call last):
  File "C:\Users\GS-0508\AppData\Local\Programs\Python\Python36-32\lib\site-packages\django\template\base.py", line 896, in _resolve_lookup
    current = current[int(bit)]
ValueError: invalid literal for int() with base 10: 'errors'

During handling of the above exception, another exception occurred:

Traceback (most recent call last):
  File "C:\Users\GS-0508\AppData\Local\Programs\Python\Python36-32\lib\site-packages\django\template\base.py", line 903, in _resolve_lookup
    (bit, current))  # missing attribute
django.template.base.VariableDoesNotExist: Failed lookup for key [errors] in 'None'
DEBUG 2018-02-05 00:01:04,746 base 19804 20216 Exception while resolving variable 'show' in template 'admin/change_list.html'.
Traceback (most recent call last):
  File "C:\Users\GS-0508\AppData\Local\Programs\Python\Python36-32\lib\site-packages\django\template\base.py", line 882, in _resolve_lookup
    current = current[bit]
  File "C:\Users\GS-0508\AppData\Local\Programs\Python\Python36-32\lib\site-packages\django\template\context.py", line 87, in __getitem__
    raise KeyError(key)
KeyError: 'show'

During handling of the above exception, another exception occurred:

Traceback (most recent call last):
  File "C:\Users\GS-0508\AppData\Local\Programs\Python\Python36-32\lib\site-packages\django\template\base.py", line 888, in _resolve_lookup
    if isinstance(current, BaseContext) and getattr(type(current), bit):
AttributeError: type object 'RequestContext' has no attribute 'show'

During handling of the above exception, another exception occurred:

Traceback (most recent call last):
  File "C:\Users\GS-0508\AppData\Local\Programs\Python\Python36-32\lib\site-packages\django\template\base.py", line 896, in _resolve_lookup
    current = current[int(bit)]
ValueError: invalid literal for int() with base 10: 'show'

During handling of the above exception, another exception occurred:

Traceback (most recent call last):
  File "C:\Users\GS-0508\AppData\Local\Programs\Python\Python36-32\lib\site-packages\django\template\base.py", line 903, in _resolve_lookup
    (bit, current))  # missing attribute
django.template.base.VariableDoesNotExist: Failed lookup for key [show] in "[{'True': True, 'False': False, 'None': None, 'csrf_token': <SimpleLazyObject: <function csrf.<locals>._get_val at 0x04BA3270>>}]"
DEBUG 2018-02-05 00:01:04,747 base 19804 20216 Exception while resolving variable 'is_multipart' in template 'admin/change_list.html'.
Traceback (most recent call last):
  File "C:\Users\GS-0508\AppData\Local\Programs\Python\Python36-32\lib\site-packages\django\template\base.py", line 882, in _resolve_lookup
    current = current[bit]
TypeError: 'NoneType' object is not subscriptable

During handling of the above exception, another exception occurred:

Traceback (most recent call last):
  File "C:\Users\GS-0508\AppData\Local\Programs\Python\Python36-32\lib\site-packages\django\template\base.py", line 890, in _resolve_lookup
    current = getattr(current, bit)
AttributeError: 'NoneType' object has no attribute 'is_multipart'

During handling of the above exception, another exception occurred:

Traceback (most recent call last):
  File "C:\Users\GS-0508\AppData\Local\Programs\Python\Python36-32\lib\site-packages\django\template\base.py", line 896, in _resolve_lookup
    current = current[int(bit)]
ValueError: invalid literal for int() with base 10: 'is_multipart'

During handling of the above exception, another exception occurred:

Traceback (most recent call last):
  File "C:\Users\GS-0508\AppData\Local\Programs\Python\Python36-32\lib\site-packages\django\template\base.py", line 903, in _resolve_lookup
    (bit, current))  # missing attribute
django.template.base.VariableDoesNotExist: Failed lookup for key [is_multipart] in 'None'
DEBUG 2018-02-05 00:01:04,782 base 19804 20216 Exception while resolving variable 'non_field_errors' in template 'admin/change_list.html'.
Traceback (most recent call last):
  File "C:\Users\GS-0508\AppData\Local\Programs\Python\Python36-32\lib\site-packages\django\template\base.py", line 882, in _resolve_lookup
    current = current[bit]
TypeError: 'NoneType' object is not subscriptable

During handling of the above exception, another exception occurred:

Traceback (most recent call last):
  File "C:\Users\GS-0508\AppData\Local\Programs\Python\Python36-32\lib\site-packages\django\template\base.py", line 890, in _resolve_lookup
    current = getattr(current, bit)
AttributeError: 'NoneType' object has no attribute 'non_field_errors'

During handling of the above exception, another exception occurred:

Traceback (most recent call last):
  File "C:\Users\GS-0508\AppData\Local\Programs\Python\Python36-32\lib\site-packages\django\template\base.py", line 896, in _resolve_lookup
    current = current[int(bit)]
ValueError: invalid literal for int() with base 10: 'non_field_errors'

During handling of the above exception, another exception occurred:

Traceback (most recent call last):
  File "C:\Users\GS-0508\AppData\Local\Programs\Python\Python36-32\lib\site-packages\django\template\base.py", line 903, in _resolve_lookup
    (bit, current))  # missing attribute
django.template.base.VariableDoesNotExist: Failed lookup for key [non_field_errors] in 'None'
DEBUG 2018-02-05 00:01:04,783 base 19804 20216 Exception while resolving variable 'non_field_errors' in template 'admin/change_list.html'.
Traceback (most recent call last):
  File "C:\Users\GS-0508\AppData\Local\Programs\Python\Python36-32\lib\site-packages\django\template\base.py", line 882, in _resolve_lookup
    current = current[bit]
TypeError: 'NoneType' object is not subscriptable

During handling of the above exception, another exception occurred:

Traceback (most recent call last):
  File "C:\Users\GS-0508\AppData\Local\Programs\Python\Python36-32\lib\site-packages\django\template\base.py", line 890, in _resolve_lookup
    current = getattr(current, bit)
AttributeError: 'NoneType' object has no attribute 'non_field_errors'

During handling of the above exception, another exception occurred:

Traceback (most recent call last):
  File "C:\Users\GS-0508\AppData\Local\Programs\Python\Python36-32\lib\site-packages\django\template\base.py", line 896, in _resolve_lookup
    current = current[int(bit)]
ValueError: invalid literal for int() with base 10: 'non_field_errors'

During handling of the above exception, another exception occurred:

Traceback (most recent call last):
  File "C:\Users\GS-0508\AppData\Local\Programs\Python\Python36-32\lib\site-packages\django\template\base.py", line 903, in _resolve_lookup
    (bit, current))  # missing attribute
django.template.base.VariableDoesNotExist: Failed lookup for key [non_field_errors] in 'None'
INFO 2018-02-05 00:01:04,787 basehttp 19804 20216 "GET /admin/location_tracker_app/location/ HTTP/1.1" 200 4687
DEBUG 2018-02-05 00:01:04,838 utils 19804 7320 (0.001) SELECT "django_session"."session_key", "django_session"."session_data", "django_session"."expire_date" FROM "django_session" WHERE ("django_session"."session_key" = 'mz66yltn6yeqmst7fuv6sswequ3rajge' AND "django_session"."expire_date" > '2018-02-04 18:31:04.835661'); args=('mz66yltn6yeqmst7fuv6sswequ3rajge', '2018-02-04 18:31:04.835661')
DEBUG 2018-02-05 00:01:04,840 utils 19804 7320 (0.001) SELECT "Users"."last_login", "Users"."is_superuser", "Users"."id", "Users"."uuid", "Users"."email", "Users"."name", "Users"."password", "Users"."phone_number", "Users"."role", "Users"."last_login_at", "Users"."created_at", "Users"."updated_at" FROM "Users" WHERE "Users"."id" = 1; args=(1,)
INFO 2018-02-05 00:01:04,843 basehttp 19804 7320 "GET /admin/jsi18n/ HTTP/1.1" 200 3189
DEBUG 2018-02-05 00:01:07,655 utils 19804 19376 (0.001) SELECT "Users"."last_login", "Users"."is_superuser", "Users"."id", "Users"."uuid", "Users"."email", "Users"."name", "Users"."password", "Users"."phone_number", "Users"."role", "Users"."last_login_at", "Users"."created_at", "Users"."updated_at" FROM "Users" WHERE "Users"."email" = 'user1@gmail.com'; args=('user1@gmail.com',)
DEBUG 2018-02-05 00:01:07,658 utils 19804 19376 (0.001) SELECT "Users"."last_login", "Users"."is_superuser", "Users"."id", "Users"."uuid", "Users"."email", "Users"."name", "Users"."password", "Users"."phone_number", "Users"."role", "Users"."last_login_at", "Users"."created_at", "Users"."updated_at" FROM "Users" WHERE "Users"."id" = 2; args=(2,)
DEBUG 2018-02-05 00:01:07,661 utils 19804 19376 (0.000) SELECT "Locations"."id", "Locations"."lat", "Locations"."lng", "Locations"."time", "Locations"."next_location_id", "Locations"."user_id" FROM "Locations" WHERE "Locations"."user_id" = 2; args=(2,)
DEBUG 2018-02-05 00:01:07,663 utils 19804 19376 (0.000) SELECT "Users"."last_login", "Users"."is_superuser", "Users"."id", "Users"."uuid", "Users"."email", "Users"."name", "Users"."password", "Users"."phone_number", "Users"."role", "Users"."last_login_at", "Users"."created_at", "Users"."updated_at" FROM "Users" WHERE "Users"."id" = 2; args=(2,)
DEBUG 2018-02-05 00:01:07,666 utils 19804 19376 (0.000) SELECT "Users"."last_login", "Users"."is_superuser", "Users"."id", "Users"."uuid", "Users"."email", "Users"."name", "Users"."password", "Users"."phone_number", "Users"."role", "Users"."last_login_at", "Users"."created_at", "Users"."updated_at" FROM "Users" WHERE "Users"."id" = 2; args=(2,)
ERROR 2018-02-05 00:01:07,666 response 19804 19376 Success
NoneType: None
INFO 2018-02-05 00:01:07,667 basehttp 19804 19376 "GET /lct_app/v1/users/2/locations HTTP/1.1" 200 934
DEBUG 2018-02-05 00:28:43,975 utils 17796 19560 (0.001) 
            SELECT name, type FROM sqlite_master
            WHERE type in ('table', 'view') AND NOT name='sqlite_sequence'
            ORDER BY name; args=None
DEBUG 2018-02-05 00:28:43,978 utils 17796 19560 (0.000) SELECT "django_migrations"."app", "django_migrations"."name" FROM "django_migrations"; args=()
